Workbook

Sheet Dashboard
B1: CartNest: payment gateway reconciliation, September 2026
B2: All figures in INR, read live from the bridge, batch_recon, orders and mdr_check sheets (same numbers as Part A).
B4: SALES PER ORDERS | E4: CASH RECEIVED IN BANK | H4: TOTAL GAP | K4: UNEXPLAINED
B5: =bridge!B4 -> 19894293 | E5: =bridge!B19 -> 16984049 | H5: =bridge!B26 -> 2910244.4 | K5: =bridge!B27 -> 0
B6: Paid + Refunded orders | E6: 27 gateway settlements, 1-30 Sep | H6: Sales less cash in bank | K6: =IF(bridge!B27=0,"Gap fully explained by the bridge","CHECK THE BRIDGE") -> Gap fully explained by the bridge
B8: TIMING: DUE IN OCTOBER | E8: STILL OWED BY GATEWAY | H8: EXCESS FEES TO RECOVER | K8: REFUNDS PAID TO CUSTOMERS
B9: =-bridge!B16 -> 1265526.9 | E9: =-(bridge!B17+bridge!B18) -> 552324.03 | H9: =-bridge!B14 -> 1185.2 | K9: =-bridge!B11 -> 893888
B10: Batches STL-20261001 and -02 | E10: 1 missing batch + 1 short-paid batch | H10: MDR + GST charged above rate card | K10: 243 refunds, not a loss
B12: 1. Bridge: sales per orders to cash in bank
B32: Blue = totals, green = adds to cash, red = takes away from cash. Fee overcharge (₹1,185) and short-paid (₹1,250) are too small to see; see the tables below.
B34: 2. Where the gap comes from (largest first)
B35: Item | E35: Amount (INR) | F35: % of gap | G35: Nature
B36: Due in October (timing) | E36: =-bridge!B16 -> 1265526.9 | F36: =E36/$E$47 -> 0.43485244 | G36: Timing: arrives 1-2 Oct
B37: Refunds paid to customers | E37: =-bridge!B11 -> 893888 | F37: =E37/$E$47 -> 0.30715221 | G37: Expected: money returned
B38: Missing settlement STL-20260912 | E38: =-bridge!B17 -> 551074.03 | F38: =E38/$E$47 -> 0.18935661 | G38: Genuine: chase gateway
B39: Gateway fees at correct rate | E39: =-(bridge!B12+bridge!B13) -> 205776.31 | F39: =E39/$E$47 -> 0.070707569 | G39: Expected: cost of payments
B40: Paid orders with no payment | E40: =-bridge!B5 -> 67617 | F40: =E40/$E$47 -> 0.023234131 | G40: Genuine: investigate orders
B41: Amount differences | E41: =-bridge!B6 -> 3145 | F41: =E41/$E$47 -> 0.0010806652 | G41: Genuine: gateway collected less
B42: Short-paid batch STL-20260911 | E42: =-bridge!B18 -> 1250 | F42: =E42/$E$47 -> 0.00042951719 | G42: Genuine: chase gateway
B43: Excess MDR + GST charged | E43: =-bridge!B14 -> 1185.2 | F43: =E43/$E$47 -> 0.00040725101 | G43: Genuine: recover from gateway
B44: Payments with no order | E44: =-bridge!B8 -> -24992 | F44: =E44/$E$47 -> -0.0085875948 | G44: Offsets gap: identify payer
B45: Duplicate charges | E45: =-bridge!B7 -> -25539 | F45: =E45/$E$47 -> -0.0087755515 | G45: Offsets gap: refund customers
B46: Payments on Failed/Cancelled orders | E46: =-bridge!B9 -> -28687 | F46: =E46/$E$47 -> -0.0098572476 | G46: Offsets gap: refund customers
B47: Total gap | E47: =SUM(E36:E46) -> 2910244.4 | F47: =SUM(F36:F46) -> 1 | G47: =IF(ROUND(E47-bridge!B26,2)=0,"Agrees with bridge","DOES NOT AGREE") -> Agrees with bridge
B50: 3. Exceptions by type (count and rupee value)
B51: Exception | E51: Count | F51: Value (INR) | G51: Nature
B52: Due in October (batches) | E52: =COUNTIF(batch_recon!F:F,"Due in October") -> 2 | F52: =-bridge!B16 -> 1265526.9 | G52: Timing
B53: Missing settlement (batches) | E53: =COUNTIF(batch_recon!F:F,"Missing") -> 1 | F53: =-bridge!B17 -> 551074.03 | G53: Genuine: chase gateway
B54: Paid orders with no payment | E54: =COUNTIF(orders!N:N,"Paid, no payment") -> 20 | F54: =SUMIF(orders!N:N,"Paid, no payment",orders!O:O) -> 67617 | G54: Genuine: investigate
B55: Refunded orders with no refund | E55: =COUNTIF(orders!N:N,"Refunded, no refund") -> 6 | F55: =SUMIF(orders!N:N,"Refunded, no refund",orders!O:O) -> 29889 | G55: Customer refund due
B56: Payments on Failed/Cancelled orders | E56: =COUNTIF(orders!N:N,"Payment on failed/cancelled") -> 8 | F56: =SUMIF(orders!N:N,"Payment on failed/cancelled",orders!O:O) -> 28687 | G56: Customer refund due
B57: Duplicate charges (extra amount) | E57: =COUNTIF(orders!N:N,"Duplicate charge") -> 6 | F57: =SUMIF(orders!N:N,"Duplicate charge",orders!O:O) -> 25539 | G57: Customer refund due
B58: Payments with no order | E58: =COUNTIF(pg_transaction_cleaned!Q:Q,"NO ORDER") -> 8 | F58: =SUMIFS(pg_transaction_cleaned!H:H,pg_transaction_cleaned!Q:Q,"NO ORDER") -> 24992 | G58: Identify payer
B59: Refund given, order not Refunded | E59: =COUNTIF(orders!N:N,"Refund, order not Refunded") -> 7 | F59: =SUMIF(orders!N:N,"Refund, order not Refunded",orders!O:O) -> 13886 | G59: Fix order status
B60: Amount differences | E60: =COUNTIF(orders!N:N,"Amount difference") -> 15 | F60: =ABS(SUMIF(orders!N:N,"Amount difference",orders!O:O)) -> 3145 | G60: Genuine: gateway lower
B61: Short-paid settlement (batches) | E61: =COUNTIF(batch_recon!F:F,"Short-paid") -> 1 | F61: =-bridge!B18 -> 1250 | G61: Genuine: chase gateway
B62: MDR + GST overcharge (payments) | E62: =COUNTIF(mdr_check!L:L,">0") -> 55 | F62: =SUM(mdr_check!L:L) -> 1185.2 | G62: Genuine: recover
B63: Refund amount differs from order | E63: =COUNTIF(orders!N:N,"Refund amount differs") -> 0 | F63: =SUMIF(orders!N:N,"Refund amount differs",orders!O:O) -> 0 | G63: None found
B65: Counts are orders or payments, except rows marked batches (settlement batches). Value for duplicates is the extra amount charged.
B67: 4. Daily settlements vs bank receipts
...

Sheet bridge
A1: Bridge: sales per orders to cash in bank (INR)
A3: Line | B3: Amount (INR) | C3: Source
A4: Sales per orders (Paid + Refunded) | B4: =SUMIFS(orders!H:H,orders!G:G,"Paid")+SUMIFS(orders!H:H,orders!G:G,"Refunded") -> 19894293 | C4: orders: order_amount_cleaned by order_status
A5: Paid orders with no payment | B5: =-SUMIFS(orders!O:O,orders!N:N,"Paid, no payment") -> -67617 | C5: orders: exception_type
A6: Amount differences | B6: =SUMIFS(orders!O:O,orders!N:N,"Amount difference") -> -3145 | C6: orders: exception_type (already signed)
A7: Duplicate charges | B7: =SUMIFS(orders!O:O,orders!N:N,"Duplicate charge") -> 25539 | C7: orders: exception_type (extra amount charged)
A8: Payments with no order | B8: =SUMIFS(pg_transaction_cleaned!H:H,pg_transaction_cleaned!Q:Q,"NO ORDER") -> 24992 | C8: pg cleaned: order_found = NO ORDER
A9: Payments on Failed/Cancelled orders | B9: =SUMIFS(orders!O:O,orders!N:N,"Payment on failed/cancelled") -> 28687 | C9: orders: exception_type
A10: Gross captured by gateway | B10: =SUM(B4:B9) -> 19902749 | C10: subtotal
A11: Refunds | B11: =-SUMIFS(pg_transaction_cleaned!H:H,pg_transaction_cleaned!F:F,"REFUND") -> -893888 | C11: pg cleaned: REFUND gross
A12: MDR (at the correct rate) | B12: =-SUM(mdr_check!H:H) -> -174385.11 | C12: mdr_check: expected_mdr
A13: GST on MDR (correct) | B13: =-SUM(mdr_check!K:K) -> -31391.2 | C13: mdr_check: expected_gst
A14: MDR + GST overcharge | B14: =-SUM(mdr_check!L:L) -> -1185.2 | C14: mdr_check: (fee + GST charged) less correct
A15: Net payable by gateway | B15: =B10+SUM(B11:B14) -> 18801899 | C15: subtotal
A16: Due in October | B16: =-SUMIFS(batch_recon!C:C,batch_recon!F:F,"Due in October")+SUMIFS(batch_recon!D:D,batch_recon!F:F,"Due in October") -> -1265526.9 | C16: batch_recon
A17: Missing settlement (STL-20260912) | B17: =SUMIFS(batch_recon!D:D,batch_recon!F:F,"Missing")-SUMIFS(batch_recon!C:C,batch_recon!F:F,"Missing") -> -551074.03 | C17: batch_recon
A18: Short-paid (STL-20260911) | B18: =SUMIFS(batch_recon!D:D,batch_recon!F:F,"Short-paid")-SUMIFS(batch_recon!C:C,batch_recon!F:F,"Short-paid") -> -1250 | C18: batch_recon
A19: Cash in bank | B19: =B15+SUM(B16:B18) -> 16984049 | C19: subtotal
A21: CHECKS
A22: Bank credits on gateway batches (actual) | B22: =SUM(batch_recon!D2:D31) -> 16984049 | C22: batch_recon
A23: Check: bridge cash in bank less bank total (must be 0) | B23: =ROUND(B19-B22,2) -> 0
A24: Check: gross captured less gateway captures (must be 0) | B24: =ROUND(B10-SUMIFS(pg_transaction_cleaned!H:H,pg_transaction_cleaned!F:F,"CAPTURE"),2) -> 0
A25: Check: net payable less sum of gateway net (must be 0) | B25: =ROUND(B15-SUM(pg_transaction_cleaned!K:K),2) -> 0
A26: Total gap (sales less cash in bank) | B26: =B4-B19 -> 2910244.4
A27: Unexplained difference | B27: =ROUND((B19-B4)-(SUM(B5:B9)+B11+B12+B13+B14+SUM(B16:B18)),2) -> 0 | C27: sum of all adjustment lines vs gap

Sheet batch_recon
A1: batch_id | B1: settlement_date | C1: gateway_net | D1: bank_credit | E1: difference | F1: status | H1: Summary by status
A2: STL-20260903 | B2: =DATE(MID(A2,5,4),MID(A2,9,2),RIGHT(A2,2)) -> 46268 | C2: =SUMIFS(pg_transaction_cleaned!$K:$K,pg_transaction_cleaned!$M:$M,A2) -> 463778.55 | D2: =SUMIFS(bank_statement_cleaned!$G:$G,bank_statement_cleaned!$H:$H,A2) -> 463778.55 | E2: =D2-C2 -> 0 | F2: =IF(B2>DATE(2026,9,30),"Due in October",IF(COUNTIF(bank_statement_cleaned!$H:$H,A2)=0,"Missing",IF(ROUND(E2,2)=0,"Matched",IF(E2<0,"Short-paid","Excess")))) -> Matched | H2: Status | I2: Batches | J2: Gateway net | K2: Bank credit | L2: Difference (bank - gateway)
A3: STL-20260904 | B3: =DATE(MID(A3,5,4),MID(A3,9,2),RIGHT(A3,2)) -> 46269 | C3: =SUMIFS(pg_transaction_cleaned!$K:$K,pg_transaction_cleaned!$M:$M,A3) -> 680913.82 | D3: =SUMIFS(bank_statement_cleaned!$G:$G,bank_statement_cleaned!$H:$H,A3) -> 680913.82 | E3: =D3-C3 -> 0 | F3: =IF(B3>DATE(2026,9,30),"Due in October",IF(COUNTIF(bank_statement_cleaned!$H:$H,A3)=0,"Missing",IF(ROUND(E3,2)=0,"Matched",IF(E3<0,"Short-paid","Excess")))) -> Matched | H3: Matched | I3: =COUNTIF($F$2:$F$31,H3) -> 26 | J3: =SUMIF($F$2:$F$31,H3,$C$2:$C$31) -> 16428887 | K3: =SUMIF($F$2:$F$31,H3,$D$2:$D$31) -> 16428887 | L3: =K3-J3 -> 0
A4: STL-20260905 | B4: =DATE(MID(A4,5,4),MID(A4,9,2),RIGHT(A4,2)) -> 46270 | C4: =SUMIFS(pg_transaction_cleaned!$K:$K,pg_transaction_cleaned!$M:$M,A4) -> 578249.99 | D4: =SUMIFS(bank_statement_cleaned!$G:$G,bank_statement_cleaned!$H:$H,A4) -> 578249.99 | E4: =D4-C4 -> 0 | F4: =IF(B4>DATE(2026,9,30),"Due in October",IF(COUNTIF(bank_statement_cleaned!$H:$H,A4)=0,"Missing",IF(ROUND(E4,2)=0,"Matched",IF(E4<0,"Short-paid","Excess")))) -> Matched | H4: Short-paid | I4: =COUNTIF($F$2:$F$31,H4) -> 1 | J4: =SUMIF($F$2:$F$31,H4,$C$2:$C$31) -> 556411.99 | K4: =SUMIF($F$2:$F$31,H4,$D$2:$D$31) -> 555161.99 | L4: =K4-J4 -> -1250
A5: STL-20260906 | B5: =DATE(MID(A5,5,4),MID(A5,9,2),RIGHT(A5,2)) -> 46271 | C5: =SUMIFS(pg_transaction_cleaned!$K:$K,pg_transaction_cleaned!$M:$M,A5) -> 655139.18 | D5: =SUMIFS(bank_statement_cleaned!$G:$G,bank_statement_cleaned!$H:$H,A5) -> 655139.18 | E5: =D5-C5 -> 0 | F5: =IF(B5>DATE(2026,9,30),"Due in October",IF(COUNTIF(bank_statement_cleaned!$H:$H,A5)=0,"Missing",IF(ROUND(E5,2)=0,"Matched",IF(E5<0,"Short-paid","Excess")))) -> Matched | H5: Missing | I5: =COUNTIF($F$2:$F$31,H5) -> 1 | J5: =SUMIF($F$2:$F$31,H5,$C$2:$C$31) -> 551074.03 | K5: =SUMIF($F$2:$F$31,H5,$D$2:$D$31) -> 0 | L5: =K5-J5 -> -551074.03
A6: STL-20260907 | B6: =DATE(MID(A6,5,4),MID(A6,9,2),RIGHT(A6,2)) -> 46272 | C6: =SUMIFS(pg_transaction_cleaned!$K:$K,pg_transaction_cleaned!$M:$M,A6) -> 614451.5 | D6: =SUMIFS(bank_statement_cleaned!$G:$G,bank_statement_cleaned!$H:$H,A6) -> 614451.5 | E6: =D6-C6 -> 0 | F6: =IF(B6>DATE(2026,9,30),"Due in October",IF(COUNTIF(bank_statement_cleaned!$H:$H,A6)=0,"Missing",IF(ROUND(E6,2)=0,"Matched",IF(E6<0,"Short-paid","Excess")))) -> Matched | H6: Due in October | I6: =COUNTIF($F$2:$F$31,H6) -> 2 | J6: =SUMIF($F$2:$F$31,H6,$C$2:$C$31) -> 1265526.9 | K6: =SUMIF($F$2:$F$31,H6,$D$2:$D$31) -> 0 | L6: =K6-J6 -> -1265526.9
A7: STL-20260908 | B7: =DATE(MID(A7,5,4),MID(A7,9,2),RIGHT(A7,2)) -> 46273 | C7: =SUMIFS(pg_transaction_cleaned!$K:$K,pg_transaction_cleaned!$M:$M,A7) -> 704983.27 | D7: =SUMIFS(bank_statement_cleaned!$G:$G,bank_statement_cleaned!$H:$H,A7) -> 704983.27 | E7: =D7-C7 -> 0 | F7: =IF(B7>DATE(2026,9,30),"Due in October",IF(COUNTIF(bank_statement_cleaned!$H:$H,A7)=0,"Missing",IF(ROUND(E7,2)=0,"Matched",IF(E7<0,"Short-paid","Excess")))) -> Matched | H7: Excess | I7: =COUNTIF($F$2:$F$31,H7) -> 0 | J7: =SUMIF($F$2:$F$31,H7,$C$2:$C$31) -> 0 | K7: =SUMIF($F$2:$F$31,H7,$D$2:$D$31) -> 0 | L7: =K7-J7 -> 0
A8: STL-20260909 | B8: =DATE(MID(A8,5,4),MID(A8,9,2),RIGHT(A8,2)) -> 46274 | C8: =SUMIFS(pg_transaction_cleaned!$K:$K,pg_transaction_cleaned!$M:$M,A8) -> 606316.51 | D8: =SUMIFS(bank_statement_cleaned!$G:$G,bank_statement_cleaned!$H:$H,A8) -> 606316.51 | E8: =D8-C8 -> 0 | F8: =IF(B8>DATE(2026,9,30),"Due in October",IF(COUNTIF(bank_statement_cleaned!$H:$H,A8)=0,"Missing",IF(ROUND(E8,2)=0,"Matched",IF(E8<0,"Short-paid","Excess")))) -> Matched | H8: Total | I8: =SUM(I3:I7) -> 30 | J8: =SUM(J3:J7) -> 18801899 | K8: =SUM(K3:K7) -> 16984049 | L8: =SUM(L3:L7) -> -1817850.9
A9: STL-20260910 | B9: =DATE(MID(A9,5,4),MID(A9,9,2),RIGHT(A9,2)) -> 46275 | C9: =SUMIFS(pg_transaction_cleaned!$K:$K,pg_transaction_cleaned!$M:$M,A9) -> 740734.12 | D9: =SUMIFS(bank_statement_cleaned!$G:$G,bank_statement_cleaned!$H:$H,A9) -> 740734.12 | E9: =D9-C9 -> 0 | F9: =IF(B9>DATE(2026,9,30),"Due in October",IF(COUNTIF(bank_statement_cleaned!$H:$H,A9)=0,"Missing",IF(ROUND(E9,2)=0,"Matched",IF(E9<0,"Short-paid","Excess")))) -> Matched
A10: STL-20260911 | B10: =DATE(MID(A10,5,4),MID(A10,9,2),RIGHT(A10,2)) -> 46276 | C10: =SUMIFS(pg_transaction_cleaned!$K:$K,pg_transaction_cleaned!$M:$M,A10) -> 556411.99 | D10: =SUMIFS(bank_statement_cleaned!$G:$G,bank_statement_cleaned!$H:$H,A10) -> 555161.99 | E10: =D10-C10 -> -1250 | F10: =IF(B10>DATE(2026,9,30),"Due in October",IF(COUNTIF(bank_statement_cleaned!$H:$H,A10)=0,"Missing",IF(ROUND(E10,2)=0,"Matched",IF(E10<0,"Short-paid","Excess")))) -> Short-paid
A11: STL-20260912 | B11: =DATE(MID(A11,5,4),MID(A11,9,2),RIGHT(A11,2)) -> 46277 | C11: =SUMIFS(pg_transaction_cleaned!$K:$K,pg_transaction_cleaned!$M:$M,A11) -> 551074.03 | D11: =SUMIFS(bank_statement_cleaned!$G:$G,bank_statement_cleaned!$H:$H,A11) -> 0 | E11: =D11-C11 -> -551074.03 | F11: =IF(B11>DATE(2026,9,30),"Due in October",IF(COUNTIF(bank_statement_cleaned!$H:$H,A11)=0,"Missing",IF(ROUND(E11,2)=0,"Matched",IF(E11<0,"Short-paid","Excess")))) -> Missing | H11: Checks (blue = expected)
A12: STL-20260913 | B12: =DATE(MID(A12,5,4),MID(A12,9,2),RIGHT(A12,2)) -> 46278 | C12: =SUMIFS(pg_transaction_cleaned!$K:$K,pg_transaction_cleaned!$M:$M,A12) -> 654313.3 | D12: =SUMIFS(bank_statement_cleaned!$G:$G,bank_statement_cleaned!$H:$H,A12) -> 654313.3 | E12: =D12-C12 -> 0 | F12: =IF(B12>DATE(2026,9,30),"Due in October",IF(COUNTIF(bank_statement_cleaned!$H:$H,A12)=0,"Missing",IF(ROUND(E12,2)=0,"Matched",IF(E12<0,"Short-paid","Excess")))) -> Matched | H12: Check | I12: Actual | J12: Expected | K12: Status
A13: STL-20260914 | B13: =DATE(MID(A13,5,4),MID(A13,9,2),RIGHT(A13,2)) -> 46279 | C13: =SUMIFS(pg_transaction_cleaned!$K:$K,pg_transaction_cleaned!$M:$M,A13) -> 596289.91 | D13: =SUMIFS(bank_statement_cleaned!$G:$G,bank_statement_cleaned!$H:$H,A13) -> 596289.91 | E13: =D13-C13 -> 0 | F13: =IF(B13>DATE(2026,9,30),"Due in October",IF(COUNTIF(bank_statement_cleaned!$H:$H,A13)=0,"Missing",IF(ROUND(E13,2)=0,"Matched",IF(E13<0,"Short-paid","Excess")))) -> Matched | H13: Batches listed | I13: =COUNTA(A2:A31) -> 30 | J13: 30 | K13: =IF(ROUND(I13-J13,2)=0,"PASS","FAIL") -> PASS
A14: STL-20260915 | B14: =DATE(MID(A14,5,4),MID(A14,9,2),RIGHT(A14,2)) -> 46280 | C14: =SUMIFS(pg_transaction_cleaned!$K:$K,pg_transaction_cleaned!$M:$M,A14) -> 773297.25 | D14: =SUMIFS(bank_statement_cleaned!$G:$G,bank_statement_cleaned!$H:$H,A14) -> 773297.25 | E14: =D14-C14 -> 0 | F14: =IF(B14>DATE(2026,9,30),"Due in October",IF(COUNTIF(bank_statement_cleaned!$H:$H,A14)=0,"Missing",IF(ROUND(E14,2)=0,"Matched",IF(E14<0,"Short-paid","Excess")))) -> Matched | H14: Matched batches | I14: =I3 -> 26 | J14: 26 | K14: =IF(ROUND(I14-J14,2)=0,"PASS","FAIL") -> PASS
A15: STL-20260916 | B15: =DATE(MID(A15,5,4),MID(A15,9,2),RIGHT(A15,2)) -> 46281 | C15: =SUMIFS(pg_transaction_cleaned!$K:$K,pg_transaction_cleaned!$M:$M,A15) -> 614772.68 | D15: =SUMIFS(bank_statement_cleaned!$G:$G,bank_statement_cleaned!$H:$H,A15) -> 614772.68 | E15: =D15-C15 -> 0 | F15: =IF(B15>DATE(2026,9,30),"Due in October",IF(COUNTIF(bank_statement_cleaned!$H:$H,A15)=0,"Missing",IF(ROUND(E15,2)=0,"Matched",IF(E15<0,"Short-paid","Excess")))) -> Matched | H15: Short-paid batches | I15: =I4 -> 1 | J15: 1 | K15: =IF(ROUND(I15-J15,2)=0,"PASS","FAIL") -> PASS
A16: STL-20260917 | B16: =DATE(MID(A16,5,4),MID(A16,9,2),RIGHT(A16,2)) -> 46282 | C16: =SUMIFS(pg_transaction_cleaned!$K:$K,pg_transaction_cleaned!$M:$M,A16) -> 671270.49 | D16: =SUMIFS(bank_statement_cleaned!$G:$G,bank_statement_cleaned!$H:$H,A16) -> 671270.49 | E16: =D16-C16 -> 0 | F16: =IF(B16>DATE(2026,9,30),"Due in October",IF(COUNTIF(bank_statement_cleaned!$H:$H,A16)=0,"Missing",IF(ROUND(E16,2)=0,"Matched",IF(E16<0,"Short-paid","Excess")))) -> Matched | H16: Missing batches | I16: =I5 -> 1 | J16: 1 | K16: =IF(ROUND(I16-J16,2)=0,"PASS","FAIL") -> PASS
A17: STL-20260918 | B17: =DATE(MID(A17,5,4),MID(A17,9,2),RIGHT(A17,2)) -> 46283 | C17: =SUMIFS(pg_transaction_cleaned!$K:$K,pg_transaction_cleaned!$M:$M,A17) -> 589645.35 | D17: =SUMIFS(bank_statement_cleaned!$G:$G,bank_statement_cleaned!$H:$H,A17) -> 589645.35 | E17: =D17-C17 -> 0 | F17: =IF(B17>DATE(2026,9,30),"Due in October",IF(COUNTIF(bank_statement_cleaned!$H:$H,A17)=0,"Missing",IF(ROUND(E17,2)=0,"Matched",IF(E17<0,"Short-paid","Excess")))) -> Matched | H17: Due in October batches | I17: =I6 -> 2 | J17: 2 | K17: =IF(ROUND(I17-J17,2)=0,"PASS","FAIL") -> PASS
A18: STL-20260919 | B18: =DATE(MID(A18,5,4),MID(A18,9,2),RIGHT(A18,2)) -> 46284 | C18: =SUMIFS(pg_transaction_cleaned!$K:$K,pg_transaction_cleaned!$M:$M,A18) -> 610773.29 | D18: =SUMIFS(bank_statement_cleaned!$G:$G,bank_statement_cleaned!$H:$H,A18) -> 610773.29 | E18: =D18-C18 -> 0 | F18: =IF(B18>DATE(2026,9,30),"Due in October",IF(COUNTIF(bank_statement_cleaned!$H:$H,A18)=0,"Missing",IF(ROUND(E18,2)=0,"Matched",IF(E18<0,"Short-paid","Excess")))) -> Matched | H18: Excess batches | I18: =I7 -> 0 | J18: 0 | K18: =IF(ROUND(I18-J18,2)=0,"PASS","FAIL") -> PASS
A19: STL-20260920 | B19: =DATE(MID(A19,5,4),MID(A19,9,2),RIGHT(A19,2)) -> 46285 | C19: =SUMIFS(pg_transaction_cleaned!$K:$K,pg_transaction_cleaned!$M:$M,A19) -> 548940.41 | D19: =SUMIFS(bank_statement_cleaned!$G:$G,bank_statement_cleaned!$H:$H,A19) -> 548940.41 | E19: =D19-C19 -> 0 | F19: =IF(B19>DATE(2026,9,30),"Due in October",IF(COUNTIF(bank_statement_cleaned!$H:$H,A19)=0,"Missing",IF(ROUND(E19,2)=0,"Matched",IF(E19<0,"Short-paid","Excess")))) -> Matched | H19: Short-paid amount (INR) | I19: =ROUND(-L4,2) -> 1250 | J19: 1250 | K19: =IF(ROUND(I19-J19,2)=0,"PASS","FAIL") -> PASS
A20: STL-20260921 | B20: =DATE(MID(A20,5,4),MID(A20,9,2),RIGHT(A20,2)) -> 46286 | C20: =SUMIFS(pg_transaction_cleaned!$K:$K,pg_transaction_cleaned!$M:$M,A20) -> 592258.61 | D20: =SUMIFS(bank_statement_cleaned!$G:$G,bank_statement_cleaned!$H:$H,A20) -> 592258.61 | E20: =D20-C20 -> 0 | F20: =IF(B20>DATE(2026,9,30),"Due in October",IF(COUNTIF(bank_statement_cleaned!$H:$H,A20)=0,"Missing",IF(ROUND(E20,2)=0,"Matched",IF(E20<0,"Short-paid","Excess")))) -> Matched | H20: Missing amount (INR) | I20: =ROUND(J5,2) -> 551074.03 | J20: 551074.03 | K20: =IF(ROUND(I20-J20,2)=0,"PASS","FAIL") -> PASS
A21: STL-20260922 | B21: =DATE(MID(A21,5,4),MID(A21,9,2),RIGHT(A21,2)) -> 46287 | C21: =SUMIFS(pg_transaction_cleaned!$K:$K,pg_transaction_cleaned!$M:$M,A21) -> 584876.78 | D21: =SUMIFS(bank_statement_cleaned!$G:$G,bank_statement_cleaned!$H:$H,A21) -> 584876.78 | E21: =D21-C21 -> 0 | F21: =IF(B21>DATE(2026,9,30),"Due in October",IF(COUNTIF(bank_statement_cleaned!$H:$H,A21)=0,"Missing",IF(ROUND(E21,2)=0,"Matched",IF(E21<0,"Short-paid","Excess")))) -> Matched | H21: Due in October amount (INR) | I21: =ROUND(J6,2) -> 1265526.9 | J21: 1265526.9 | K21: =IF(ROUND(I21-J21,2)=0,"PASS","FAIL") -> PASS
A22: STL-20260923 | B22: =DATE(MID(A22,5,4),MID(A22,9,2),RIGHT(A22,2)) -> 46288 | C22: =SUMIFS(pg_transaction_cleaned!$K:$K,pg_transaction_cleaned!$M:$M,A22) -> 590273.39 | D22: =SUMIFS(bank_statement_cleaned!$G:$G,bank_statement_cleaned!$H:$H,A22) -> 590273.39 | E22: =D22-C22 -> 0 | F22: =IF(B22>DATE(2026,9,30),"Due in October",IF(COUNTIF(bank_statement_cleaned!$H:$H,A22)=0,"Missing",IF(ROUND(E22,2)=0,"Matched",IF(E22<0,"Short-paid","Excess")))) -> Matched | H22: Total gateway net (INR) | I22: =ROUND(C32,2) -> 18801899 | J22: 18801899 | K22: =IF(ROUND(I22-J22,2)=0,"PASS","FAIL") -> PASS
A23: STL-20260924 | B23: =DATE(MID(A23,5,4),MID(A23,9,2),RIGHT(A23,2)) -> 46289 | C23: =SUMIFS(pg_transaction_cleaned!$K:$K,pg_transaction_cleaned!$M:$M,A23) -> 540644.22 | D23: =SUMIFS(bank_statement_cleaned!$G:$G,bank_statement_cleaned!$H:$H,A23) -> 540644.22 | E23: =D23-C23 -> 0 | F23: =IF(B23>DATE(2026,9,30),"Due in October",IF(COUNTIF(bank_statement_cleaned!$H:$H,A23)=0,"Missing",IF(ROUND(E23,2)=0,"Matched",IF(E23<0,"Short-paid","Excess")))) -> Matched | H23: Gateway net ties to pg sheet (diff) | I23: =ROUND(C32-SUM(pg_transaction_cleaned!$K:$K),2) -> 0 | J23: 0 | K23: =IF(ROUND(I23-J23,2)=0,"PASS","FAIL") -> PASS
A24: STL-20260925 | B24: =DATE(MID(A24,5,4),MID(A24,9,2),RIGHT(A24,2)) -> 46290 | C24: =SUMIFS(pg_transaction_cleaned!$K:$K,pg_transaction_cleaned!$M:$M,A24) -> 594966.59 | D24: =SUMIFS(bank_statement_cleaned!$G:$G,bank_statement_cleaned!$H:$H,A24) -> 594966.59 | E24: =D24-C24 -> 0 | F24: =IF(B24>DATE(2026,9,30),"Due in October",IF(COUNTIF(bank_statement_cleaned!$H:$H,A24)=0,"Missing",IF(ROUND(E24,2)=0,"Matched",IF(E24<0,"Short-paid","Excess")))) -> Matched | H24: Total bank credit on batches (INR) | I24: =ROUND(D32,2) -> 16984049 | J24: 16984049 | K24: =IF(ROUND(I24-J24,2)=0,"PASS","FAIL") -> PASS
A25: STL-20260926 | B25: =DATE(MID(A25,5,4),MID(A25,9,2),RIGHT(A25,2)) -> 46291 | C25: =SUMIFS(pg_transaction_cleaned!$K:$K,pg_transaction_cleaned!$M:$M,A25) -> 711251.32 | D25: =SUMIFS(bank_statement_cleaned!$G:$G,bank_statement_cleaned!$H:$H,A25) -> 711251.32 | E25: =D25-C25 -> 0 | F25: =IF(B25>DATE(2026,9,30),"Due in October",IF(COUNTIF(bank_statement_cleaned!$H:$H,A25)=0,"Missing",IF(ROUND(E25,2)=0,"Matched",IF(E25<0,"Short-paid","Excess")))) -> Matched | H25: Bank gateway credits tie (diff) | I25: =ROUND(D32-SUMIF(bank_statement_cleaned!$I:$I,"Gateway",bank_statement_cleaned!$G:$G),2) -> 0 | J25: 0 | K25: =IF(ROUND(I25-J25,2)=0,"PASS","FAIL") -> PASS
A26: STL-20260927 | B26: =DATE(MID(A26,5,4),MID(A26,9,2),RIGHT(A26,2)) -> 46292 | C26: =SUMIFS(pg_transaction_cleaned!$K:$K,pg_transaction_cleaned!$M:$M,A26) -> 805057.1 | D26: =SUMIFS(bank_statement_cleaned!$G:$G,bank_statement_cleaned!$H:$H,A26) -> 805057.1 | E26: =D26-C26 -> 0 | F26: =IF(B26>DATE(2026,9,30),"Due in October",IF(COUNTIF(bank_statement_cleaned!$H:$H,A26)=0,"Missing",IF(ROUND(E26,2)=0,"Matched",IF(E26<0,"Short-paid","Excess")))) -> Matched | H26: Gap = short + missing + October (diff) | I26: =ROUND((C32-D32)-(-L4+J5+J6),2) -> 0 | J26: 0 | K26: =IF(ROUND(I26-J26,2)=0,"PASS","FAIL") -> PASS
A27: STL-20260928 | B27: =DATE(MID(A27,5,4),MID(A27,9,2),RIGHT(A27,2)) -> 46293 | C27: =SUMIFS(pg_transaction_cleaned!$K:$K,pg_transaction_cleaned!$M:$M,A27) -> 569672.43 | D27: =SUMIFS(bank_statement_cleaned!$G:$G,bank_statement_cleaned!$H:$H,A27) -> 569672.43 | E27: =D27-C27 -> 0 | F27: =IF(B27>DATE(2026,9,30),"Due in October",IF(COUNTIF(bank_statement_cleaned!$H:$H,A27)=0,"Missing",IF(ROUND(E27,2)=0,"Matched",IF(E27<0,"Short-paid","Excess")))) -> Matched
A28: STL-20260929 | B28: =DATE(MID(A28,5,4),MID(A28,9,2),RIGHT(A28,2)) -> 46294 | C28: =SUMIFS(pg_transaction_cleaned!$K:$K,pg_transaction_cleaned!$M:$M,A28) -> 641930.73 | D28: =SUMIFS(bank_statement_cleaned!$G:$G,bank_statement_cleaned!$H:$H,A28) -> 641930.73 | E28: =D28-C28 -> 0 | F28: =IF(B28>DATE(2026,9,30),"Due in October",IF(COUNTIF(bank_statement_cleaned!$H:$H,A28)=0,"Missing",IF(ROUND(E28,2)=0,"Matched",IF(E28<0,"Short-paid","Excess")))) -> Matched | H28: Checks passed | I28: =COUNTIF(K13:K26,"PASS")&" of "&COUNTA(K13:K26) -> 14 of 14
A29: STL-20260930 | B29: =DATE(MID(A29,5,4),MID(A29,9,2),RIGHT(A29,2)) -> 46295 | C29: =SUMIFS(pg_transaction_cleaned!$K:$K,pg_transaction_cleaned!$M:$M,A29) -> 694085.78 | D29: =SUMIFS(bank_statement_cleaned!$G:$G,bank_statement_cleaned!$H:$H,A29) -> 694085.78 | E29: =D29-C29 -> 0 | F29: =IF(B29>DATE(2026,9,30),"Due in October",IF(COUNTIF(bank_statement_cleaned!$H:$H,A29)=0,"Missing",IF(ROUND(E29,2)=0,"Matched",IF(E29<0,"Short-paid","Excess")))) -> Matched
A30: STL-20261001 | B30: =DATE(MID(A30,5,4),MID(A30,9,2),RIGHT(A30,2)) -> 46296 | C30: =SUMIFS(pg_transaction_cleaned!$K:$K,pg_transaction_cleaned!$M:$M,A30) -> 650622.7 | D30: =SUMIFS(bank_statement_cleaned!$G:$G,bank_statement_cleaned!$H:$H,A30) -> 0 | E30: =D30-C30 -> -650622.7 | F30: =IF(B30>DATE(2026,9,30),"Due in October",IF(COUNTIF(bank_statement_cleaned!$H:$H,A30)=0,"Missing",IF(ROUND(E30,2)=0,"Matched",IF(E30<0,"Short-paid","Excess")))) -> Due in October
A31: STL-20261002 | B31: =DATE(MID(A31,5,4),MID(A31,9,2),RIGHT(A31,2)) -> 46297 | C31: =SUMIFS(pg_transaction_cleaned!$K:$K,pg_transaction_cleaned!$M:$M,A31) -> 614904.2 | D31: =SUMIFS(bank_statement_cleaned!$G:$G,bank_statement_cleaned!$H:$H,A31) -> 0 | E31: =D31-C31 -> -614904.2 | F31: =IF(B31>DATE(2026,9,30),"Due in October",IF(COUNTIF(bank_statement_cleaned!$H:$H,A31)=0,"Missing",IF(ROUND(E31,2)=0,"Matched",IF(E31<0,"Short-paid","Excess")))) -> Due in October
A32: Total | C32: =SUM(C2:C31) -> 18801899 | D32: =SUM(D2:D31) -> 16984049 | E32: =SUM(E2:E31) -> -1817850.9

Sheet orders
A1: order_id | B1: order_date | C1: customer_id | D1: city | E1: payment_method | F1: order_amount | G1: order_status | H1: order_amount_cleaned | I1: city_clean | J1: capture_count | K1: capture_gross | L1: refund_count | M1: refund_amount | N1: exception_type | O1: exception_value
A2: ORD26000001 | B2: 46286 | C2: CUST28289 | D2: Pune | E2: UPI | F2: 299.0 | G2: Paid | H2: =VALUE(SUBSTITUTE(F2,",","")) -> 299 | I2: =IF(TRIM(D2)="","Unknown",TRIM(D2)) -> Pune | J2: =COUNTIFS(pg_transaction_cleaned!$O:$O,A2,pg_transaction_cleaned!$F:$F,"CAPTURE") -> 1 | K2: =SUMIFS(pg_transaction_cleaned!$H:$H,pg_transaction_cleaned!$O:$O,A2,pg_transaction_cleaned!$F:$F,"CAPTURE") -> 299 | L2: =COUNTIFS(pg_transaction_cleaned!$O:$O,A2,pg_transaction_cleaned!$F:$F,"REFUND") -> 0 | M2: =SUMIFS(pg_transaction_cleaned!$H:$H,pg_transaction_cleaned!$O:$O,A2,pg_transaction_cleaned!$F:$F,"REFUND") -> 0 | N2: =IF(AND(G2="Paid",J2=0),"Paid, no payment",IF(AND(OR(G2="Failed",G2="Cancelled"),J2>0),"Payment on failed/cancelled",IF(J2>1,"Duplicate charge",IF(AND(J2=1,ROUND(K2-H2,2)<>0),"Amount difference",IF(AND(G2="Refunded",L2=0),"Refunded, no refund",IF(AND(G2<>"Refunded",L2>0),"Refund, order not Refunded",IF(AND(L2>0,ROUND(M2-H2,2)<>0),"Refund amount differs","OK"))))))) -> OK | O2: =IF(N2="OK",0,IF(N2="Paid, no payment",H2,IF(N2="Payment on failed/cancelled",K2,IF(OR(N2="Duplicate charge",N2="Amount difference"),K2-H2,IF(N2="Refunded, no refund",H2,M2))))) -> 0
A3: ORD26000002 | B3: 46287 | C3: CUST38657 | D3: Bengaluru | E3: UPI | F3: 4647.0 | G3: Paid | H3: =VALUE(SUBSTITUTE(F3,",","")) -> 4647 | I3: =IF(TRIM(D3)="","Unknown",TRIM(D3)) -> Bengaluru | J3: =COUNTIFS(pg_transaction_cleaned!$O:$O,A3,pg_transaction_cleaned!$F:$F,"CAPTURE") -> 1 | K3: =SUMIFS(pg_transaction_cleaned!$H:$H,pg_transaction_cleaned!$O:$O,A3,pg_transaction_cleaned!$F:$F,"CAPTURE") -> 4647 | L3: =COUNTIFS(pg_transaction_cleaned!$O:$O,A3,pg_transaction_cleaned!$F:$F,"REFUND") -> 0 | M3: =SUMIFS(pg_transaction_cleaned!$H:$H,pg_transaction_cleaned!$O:$O,A3,pg_transaction_cleaned!$F:$F,"REFUND") -> 0 | N3: =IF(AND(G3="Paid",J3=0),"Paid, no payment",IF(AND(OR(G3="Failed",G3="Cancelled"),J3>0),"Payment on failed/cancelled",IF(J3>1,"Duplicate charge",IF(AND(J3=1,ROUND(K3-H3,2)<>0),"Amount difference",IF(AND(G3="Refunded",L3=0),"Refunded, no refund",IF(AND(G3<>"Refunded",L3>0),"Refund, order not Refunded",IF(AND(L3>0,ROUND(M3-H3,2)<>0),"Refund amount differs","OK"))))))) -> OK | O3: =IF(N3="OK",0,IF(N3="Paid, no payment",H3,IF(N3="Payment on failed/cancelled",K3,IF(OR(N3="Duplicate charge",N3="Amount difference"),K3-H3,IF(N3="Refunded, no refund",H3,M3))))) -> 0
A4: ORD26000003 | B4: 46282 | C4: CUST81426 | D4: Kolkata | E4: Card | F4: 2098.0 | G4: Paid | H4: =VALUE(SUBSTITUTE(F4,",","")) -> 2098 | I4: =IF(TRIM(D4)="","Unknown",TRIM(D4)) -> Kolkata | J4: =COUNTIFS(pg_transaction_cleaned!$O:$O,A4,pg_transaction_cleaned!$F:$F,"CAPTURE") -> 1 | K4: =SUMIFS(pg_transaction_cleaned!$H:$H,pg_transaction_cleaned!$O:$O,A4,pg_transaction_cleaned!$F:$F,"CAPTURE") -> 2098 | L4: =COUNTIFS(pg_transaction_cleaned!$O:$O,A4,pg_transaction_cleaned!$F:$F,"REFUND") -> 0 | M4: =SUMIFS(pg_transaction_cleaned!$H:$H,pg_transaction_cleaned!$O:$O,A4,pg_transaction_cleaned!$F:$F,"REFUND") -> 0 | N4: =IF(AND(G4="Paid",J4=0),"Paid, no payment",IF(AND(OR(G4="Failed",G4="Cancelled"),J4>0),"Payment on failed/cancelled",IF(J4>1,"Duplicate charge",IF(AND(J4=1,ROUND(K4-H4,2)<>0),"Amount difference",IF(AND(G4="Refunded",L4=0),"Refunded, no refund",IF(AND(G4<>"Refunded",L4>0),"Refund, order not Refunded",IF(AND(L4>0,ROUND(M4-H4,2)<>0),"Refund amount differs","OK"))))))) -> OK | O4: =IF(N4="OK",0,IF(N4="Paid, no payment",H4,IF(N4="Payment on failed/cancelled",K4,IF(OR(N4="Duplicate charge",N4="Amount difference"),K4-H4,IF(N4="Refunded, no refund",H4,M4))))) -> 0
A5: ORD26000004 | B5: 46273 | C5: CUST30926 | D5: Kolkata | E5: UPI | F5: 3298.0 | G5: Paid | H5: =VALUE(SUBSTITUTE(F5,",","")) -> 3298 | I5: =IF(TRIM(D5)="","Unknown",TRIM(D5)) -> Kolkata | J5: =COUNTIFS(pg_transaction_cleaned!$O:$O,A5,pg_transaction_cleaned!$F:$F,"CAPTURE") -> 1 | K5: =SUMIFS(pg_transaction_cleaned!$H:$H,pg_transaction_cleaned!$O:$O,A5,pg_transaction_cleaned!$F:$F,"CAPTURE") -> 3298 | L5: =COUNTIFS(pg_transaction_cleaned!$O:$O,A5,pg_transaction_cleaned!$F:$F,"REFUND") -> 0 | M5: =SUMIFS(pg_transaction_cleaned!$H:$H,pg_transaction_cleaned!$O:$O,A5,pg_transaction_cleaned!$F:$F,"REFUND") -> 0 | N5: =IF(AND(G5="Paid",J5=0),"Paid, no payment",IF(AND(OR(G5="Failed",G5="Cancelled"),J5>0),"Payment on failed/cancelled",IF(J5>1,"Duplicate charge",IF(AND(J5=1,ROUND(K5-H5,2)<>0),"Amount difference",IF(AND(G5="Refunded",L5=0),"Refunded, no refund",IF(AND(G5<>"Refunded",L5>0),"Refund, order not Refunded",IF(AND(L5>0,ROUND(M5-H5,2)<>0),"Refund amount differs","OK"))))))) -> OK | O5: =IF(N5="OK",0,IF(N5="Paid, no payment",H5,IF(N5="Payment on failed/cancelled",K5,IF(OR(N5="Duplicate charge",N5="Amount difference"),K5-H5,IF(N5="Refunded, no refund",H5,M5))))) -> 0
A6: ORD26000005 | B6: 46276 | C6: CUST23396 | D6: Pune | E6: Card | F6: 499.0 | G6: Paid | H6: =VALUE(SUBSTITUTE(F6,",","")) -> 499 | I6: =IF(TRIM(D6)="","Unknown",TRIM(D6)) -> Pune | J6: =COUNTIFS(pg_transaction_cleaned!$O:$O,A6,pg_transaction_cleaned!$F:$F,"CAPTURE") -> 1 | K6: =SUMIFS(pg_transaction_cleaned!$H:$H,pg_transaction_cleaned!$O:$O,A6,pg_transaction_cleaned!$F:$F,"CAPTURE") -> 499 | L6: =COUNTIFS(pg_transaction_cleaned!$O:$O,A6,pg_transaction_cleaned!$F:$F,"REFUND") -> 0 | M6: =SUMIFS(pg_transaction_cleaned!$H:$H,pg_transaction_cleaned!$O:$O,A6,pg_transaction_cleaned!$F:$F,"REFUND") -> 0 | N6: =IF(AND(G6="Paid",J6=0),"Paid, no payment",IF(AND(OR(G6="Failed",G6="Cancelled"),J6>0),"Payment on failed/cancelled",IF(J6>1,"Duplicate charge",IF(AND(J6=1,ROUND(K6-H6,2)<>0),"Amount difference",IF(AND(G6="Refunded",L6=0),"Refunded, no refund",IF(AND(G6<>"Refunded",L6>0),"Refund, order not Refunded",IF(AND(L6>0,ROUND(M6-H6,2)<>0),"Refund amount differs","OK"))))))) -> OK | O6: =IF(N6="OK",0,IF(N6="Paid, no payment",H6,IF(N6="Payment on failed/cancelled",K6,IF(OR(N6="Duplicate charge",N6="Amount difference"),K6-H6,IF(N6="Refunded, no refund",H6,M6))))) -> 0
A7: ORD26000006 | B7: 46278 | C7: CUST15695 | D7: Ahmedabad | E7: Card | F7: 999.0 | G7: Paid | H7: =VALUE(SUBSTITUTE(F7,",","")) -> 999 | I7: =IF(TRIM(D7)="","Unknown",TRIM(D7)) -> Ahmedabad | J7: =COUNTIFS(pg_transaction_cleaned!$O:$O,A7,pg_transaction_cleaned!$F:$F,"CAPTURE") -> 1 | K7: =SUMIFS(pg_transaction_cleaned!$H:$H,pg_transaction_cleaned!$O:$O,A7,pg_transaction_cleaned!$F:$F,"CAPTURE") -> 999 | L7: =COUNTIFS(pg_transaction_cleaned!$O:$O,A7,pg_transaction_cleaned!$F:$F,"REFUND") -> 0 | M7: =SUMIFS(pg_transaction_cleaned!$H:$H,pg_transaction_cleaned!$O:$O,A7,pg_transaction_cleaned!$F:$F,"REFUND") -> 0 | N7: =IF(AND(G7="Paid",J7=0),"Paid, no payment",IF(AND(OR(G7="Failed",G7="Cancelled"),J7>0),"Payment on failed/cancelled",IF(J7>1,"Duplicate charge",IF(AND(J7=1,ROUND(K7-H7,2)<>0),"Amount difference",IF(AND(G7="Refunded",L7=0),"Refunded, no refund",IF(AND(G7<>"Refunded",L7>0),"Refund, order not Refunded",IF(AND(L7>0,ROUND(M7-H7,2)<>0),"Refund amount differs","OK"))))))) -> OK | O7: =IF(N7="OK",0,IF(N7="Paid, no payment",H7,IF(N7="Payment on failed/cancelled",K7,IF(OR(N7="Duplicate charge",N7="Amount difference"),K7-H7,IF(N7="Refunded, no refund",H7,M7))))) -> 0
A8: ORD26000007 | B8: 46283 | C8: CUST92397 | D8: Lucknow | E8: UPI | F8: 1299.0 | G8: Paid | H8: =VALUE(SUBSTITUTE(F8,",","")) -> 1299 | I8: =IF(TRIM(D8)="","Unknown",TRIM(D8)) -> Lucknow | J8: =COUNTIFS(pg_transaction_cleaned!$O:$O,A8,pg_transaction_cleaned!$F:$F,"CAPTURE") -> 1 | K8: =SUMIFS(pg_transaction_cleaned!$H:$H,pg_transaction_cleaned!$O:$O,A8,pg_transaction_cleaned!$F:$F,"CAPTURE") -> 1299 | L8: =COUNTIFS(pg_transaction_cleaned!$O:$O,A8,pg_transaction_cleaned!$F:$F,"REFUND") -> 0 | M8: =SUMIFS(pg_transaction_cleaned!$H:$H,pg_transaction_cleaned!$O:$O,A8,pg_transaction_cleaned!$F:$F,"REFUND") -> 0 | N8: =IF(AND(G8="Paid",J8=0),"Paid, no payment",IF(AND(OR(G8="Failed",G8="Cancelled"),J8>0),"Payment on failed/cancelled",IF(J8>1,"Duplicate charge",IF(AND(J8=1,ROUND(K8-H8,2)<>0),"Amount difference",IF(AND(G8="Refunded",L8=0),"Refunded, no refund",IF(AND(G8<>"Refunded",L8>0),"Refund, order not Refunded",IF(AND(L8>0,ROUND(M8-H8,2)<>0),"Refund amount differs","OK"))))))) -> OK | O8: =IF(N8="OK",0,IF(N8="Paid, no payment",H8,IF(N8="Payment on failed/cancelled",K8,IF(OR(N8="Duplicate charge",N8="Amount difference"),K8-H8,IF(N8="Refunded, no refund",H8,M8))))) -> 0
A9: ORD26000008 | B9: 46294 | C9: CUST96673 | D9: Bengaluru | E9: UPI | F9: 2499.0 | G9: Paid | H9: =VALUE(SUBSTITUTE(F9,",","")) -> 2499 | I9: =IF(TRIM(D9)="","Unknown",TRIM(D9)) -> Bengaluru | J9: =COUNTIFS(pg_transaction_cleaned!$O:$O,A9,pg_transaction_cleaned!$F:$F,"CAPTURE") -> 1 | K9: =SUMIFS(pg_transaction_cleaned!$H:$H,pg_transaction_cleaned!$O:$O,A9,pg_transaction_cleaned!$F:$F,"CAPTURE") -> 2499 | L9: =COUNTIFS(pg_transaction_cleaned!$O:$O,A9,pg_transaction_cleaned!$F:$F,"REFUND") -> 0 | M9: =SUMIFS(pg_transaction_cleaned!$H:$H,pg_transaction_cleaned!$O:$O,A9,pg_transaction_cleaned!$F:$F,"REFUND") -> 0 | N9: =IF(AND(G9="Paid",J9=0),"Paid, no payment",IF(AND(OR(G9="Failed",G9="Cancelled"),J9>0),"Payment on failed/cancelled",IF(J9>1,"Duplicate charge",IF(AND(J9=1,ROUND(K9-H9,2)<>0),"Amount difference",IF(AND(G9="Refunded",L9=0),"Refunded, no refund",IF(AND(G9<>"Refunded",L9>0),"Refund, order not Refunded",IF(AND(L9>0,ROUND(M9-H9,2)<>0),"Refund amount differs","OK"))))))) -> OK | O9: =IF(N9="OK",0,IF(N9="Paid, no payment",H9,IF(N9="Payment on failed/cancelled",K9,IF(OR(N9="Duplicate charge",N9="Amount difference"),K9-H9,IF(N9="Refunded, no refund",H9,M9))))) -> 0
A10: ORD26000009 | B10: 46290 | C10: CUST59823 | D10: Hyderabad | E10: NetBanking | F10: 349.0 | G10: Paid | H10: =VALUE(SUBSTITUTE(F10,",","")) -> 349 | I10: =IF(TRIM(D10)="","Unknown",TRIM(D10)) -> Hyderabad | J10: =COUNTIFS(pg_transaction_cleaned!$O:$O,A10,pg_transaction_cleaned!$F:$F,"CAPTURE") -> 1 | K10: =SUMIFS(pg_transaction_cleaned!$H:$H,pg_transaction_cleaned!$O:$O,A10,pg_transaction_cleaned!$F:$F,"CAPTURE") -> 349 | L10: =COUNTIFS(pg_transaction_cleaned!$O:$O,A10,pg_transaction_cleaned!$F:$F,"REFUND") -> 0 | M10: =SUMIFS(pg_transaction_cleaned!$H:$H,pg_transaction_cleaned!$O:$O,A10,pg_transaction_cleaned!$F:$F,"REFUND") -> 0 | N10: =IF(AND(G10="Paid",J10=0),"Paid, no payment",IF(AND(OR(G10="Failed",G10="Cancelled"),J10>0),"Payment on failed/cancelled",IF(J10>1,"Duplicate charge",IF(AND(J10=1,ROUND(K10-H10,2)<>0),"Amount difference",IF(AND(G10="Refunded",L10=0),"Refunded, no refund",IF(AND(G10<>"Refunded",L10>0),"Refund, order not Refunded",IF(AND(L10>0,ROUND(M10-H10,2)<>0),"Refund amount differs","OK"))))))) -> OK | O10: =IF(N10="OK",0,IF(N10="Paid, no payment",H10,IF(N10="Payment on failed/cancelled",K10,IF(OR(N10="Duplicate charge",N10="Amount difference"),K10-H10,IF(N10="Refunded, no refund",H10,M10))))) -> 0
A11: ORD26000010 | B11: 46280 | C11: CUST44993 | D11: Pune | E11: UPI | F11: 9497.0 | G11: Paid | H11: =VALUE(SUBSTITUTE(F11,",","")) -> 9497 | I11: =IF(TRIM(D11)="","Unknown",TRIM(D11)) -> Pune | J11: =COUNTIFS(pg_transaction_cleaned!$O:$O,A11,pg_transaction_cleaned!$F:$F,"CAPTURE") -> 1 | K11: =SUMIFS(pg_transaction_cleaned!$H:$H,pg_transaction_cleaned!$O:$O,A11,pg_transaction_cleaned!$F:$F,"CAPTURE") -> 9497 | L11: =COUNTIFS(pg_transaction_cleaned!$O:$O,A11,pg_transaction_cleaned!$F:$F,"REFUND") -> 0 | M11: =SUMIFS(pg_transaction_cleaned!$H:$H,pg_transaction_cleaned!$O:$O,A11,pg_transaction_cleaned!$F:$F,"REFUND") -> 0 | N11: =IF(AND(G11="Paid",J11=0),"Paid, no payment",IF(AND(OR(G11="Failed",G11="Cancelled"),J11>0),"Payment on failed/cancelled",IF(J11>1,"Duplicate charge",IF(AND(J11=1,ROUND(K11-H11,2)<>0),"Amount difference",IF(AND(G11="Refunded",L11=0),"Refunded, no refund",IF(AND(G11<>"Refunded",L11>0),"Refund, order not Refunded",IF(AND(L11>0,ROUND(M11-H11,2)<>0),"Refund amount differs","OK"))))))) -> OK | O11: =IF(N11="OK",0,IF(N11="Paid, no payment",H11,IF(N11="Payment on failed/cancelled",K11,IF(OR(N11="Duplicate charge",N11="Amount difference"),K11-H11,IF(N11="Refunded, no refund",H11,M11))))) -> 0
A12: ORD26000011 | B12: 46285 | C12: CUST45382 | D12: Jaipur | E12: UPI | F12: 5797.0 | G12: Paid | H12: =VALUE(SUBSTITUTE(F12,",","")) -> 5797 | I12: =IF(TRIM(D12)="","Unknown",TRIM(D12)) -> Jaipur | J12: =COUNTIFS(pg_transaction_cleaned!$O:$O,A12,pg_transaction_cleaned!$F:$F,"CAPTURE") -> 1 | K12: =SUMIFS(pg_transaction_cleaned!$H:$H,pg_transaction_cleaned!$O:$O,A12,pg_transaction_cleaned!$F:$F,"CAPTURE") -> 5797 | L12: =COUNTIFS(pg_transaction_cleaned!$O:$O,A12,pg_transaction_cleaned!$F:$F,"REFUND") -> 0 | M12: =SUMIFS(pg_transaction_cleaned!$H:$H,pg_transaction_cleaned!$O:$O,A12,pg_transaction_cleaned!$F:$F,"REFUND") -> 0 | N12: =IF(AND(G12="Paid",J12=0),"Paid, no payment",IF(AND(OR(G12="Failed",G12="Cancelled"),J12>0),"Payment on failed/cancelled",IF(J12>1,"Duplicate charge",IF(AND(J12=1,ROUND(K12-H12,2)<>0),"Amount difference",IF(AND(G12="Refunded",L12=0),"Refunded, no refund",IF(AND(G12<>"Refunded",L12>0),"Refund, order not Refunded",IF(AND(L12>0,ROUND(M12-H12,2)<>0),"Refund amount differs","OK"))))))) -> OK | O12: =IF(N12="OK",0,IF(N12="Paid, no payment",H12,IF(N12="Payment on failed/cancelled",K12,IF(OR(N12="Duplicate charge",N12="Amount difference"),K12-H12,IF(N12="Refunded, no refund",H12,M12))))) -> 0
A13: ORD26000012 | B13: 46273 | C13: CUST14207 | D13: Chennai | E13: UPI | F13: 13997.0 | G13: Paid | H13: =VALUE(SUBSTITUTE(F13,",","")) -> 13997 | I13: =IF(TRIM(D13)="","Unknown",TRIM(D13)) -> Chennai | J13: =COUNTIFS(pg_transaction_cleaned!$O:$O,A13,pg_transaction_cleaned!$F:$F,"CAPTURE") -> 1 | K13: =SUMIFS(pg_transaction_cleaned!$H:$H,pg_transaction_cleaned!$O:$O,A13,pg_transaction_cleaned!$F:$F,"CAPTURE") -> 13997 | L13: =COUNTIFS(pg_transaction_cleaned!$O:$O,A13,pg_transaction_cleaned!$F:$F,"REFUND") -> 0 | M13: =SUMIFS(pg_transaction_cleaned!$H:$H,pg_transaction_cleaned!$O:$O,A13,pg_transaction_cleaned!$F:$F,"REFUND") -> 0 | N13: =IF(AND(G13="Paid",J13=0),"Paid, no payment",IF(AND(OR(G13="Failed",G13="Cancelled"),J13>0),"Payment on failed/cancelled",IF(J13>1,"Duplicate charge",IF(AND(J13=1,ROUND(K13-H13,2)<>0),"Amount difference",IF(AND(G13="Refunded",L13=0),"Refunded, no refund",IF(AND(G13<>"Refunded",L13>0),"Refund, order not Refunded",IF(AND(L13>0,ROUND(M13-H13,2)<>0),"Refund amount differs","OK"))))))) -> OK | O13: =IF(N13="OK",0,IF(N13="Paid, no payment",H13,IF(N13="Payment on failed/cancelled",K13,IF(OR(N13="Duplicate charge",N13="Amount difference"),K13-H13,IF(N13="Refunded, no refund",H13,M13))))) -> 0
... A80: ORD26000079 | B80: 46285 | C80: CUST76162 | D80: Kolkata | E80: Card | F80: 4999.0 | G80: Failed | H80: =VALUE(SUBSTITUTE(F80,",","")) -> 4999 | I80: =IF(TRIM(D80)="","Unknown",TRIM(D80)) -> Kolkata | J80: =COUNTIFS(pg_transaction_cleaned!$O:$O,A80,pg_transaction_cleaned!$F:$F,"CAPTURE") -> 0 | K80: =SUMIFS(pg_transaction_cleaned!$H:$H,pg_transaction_cleaned!$O:$O,A80,pg_transaction_cleaned!$F:$F,"CAPTURE") -> 0 | L80: =COUNTIFS(pg_transaction_cleaned!$O:$O,A80,pg_transaction_cleaned!$F:$F,"REFUND") -> 0 | M80: =SUMIFS(pg_transaction_cleaned!$H:$H,pg_transaction_cleaned!$O:$O,A80,pg_transaction_cleaned!$F:$F,"REFUND") -> 0 | N80: =IF(AND(G80="Paid",J80=0),"Paid, no payment",IF(AND(OR(G80="Failed",G80="Cancelled"),J80>0),"Payment on failed/cancelled",IF(J80>1,"Duplicate charge",IF(AND(J80=1,ROUND(K80-H80,2)<>0),"Amount difference",IF(AND(G80="Refunded",L80=0),"Refunded, no refund",IF(AND(G80<>"Refunded",L80>0),"Refund, order not Refunded",IF(AND(L80>0,ROUND(M80-H80,2)<>0),"Refund amount differs","OK"))))))) -> OK | O80: =IF(N80="OK",0,IF(N80="Paid, no payment",H80,IF(N80="Payment on failed/cancelled",K80,IF(OR(N80="Duplicate charge",N80="Amount difference"),K80-H80,IF(N80="Refunded, no refund",H80,M80))))) -> 0
A81: ORD26000080 | B81: 46292 | C81: CUST43972 | E81: UPI | F81: 1998.0 | G81: Paid | H81: =VALUE(SUBSTITUTE(F81,",","")) -> 1998 | I81: =IF(TRIM(D81)="","Unknown",TRIM(D81)) -> Unknown | J81: =COUNTIFS(pg_transaction_cleaned!$O:$O,A81,pg_transaction_cleaned!$F:$F,"CAPTURE") -> 1 | K81: =SUMIFS(pg_transaction_cleaned!$H:$H,pg_transaction_cleaned!$O:$O,A81,pg_transaction_cleaned!$F:$F,"CAPTURE") -> 1998 | L81: =COUNTIFS(pg_transaction_cleaned!$O:$O,A81,pg_transaction_cleaned!$F:$F,"REFUND") -> 0 | M81: =SUMIFS(pg_transaction_cleaned!$H:$H,pg_transaction_cleaned!$O:$O,A81,pg_transaction_cleaned!$F:$F,"REFUND") -> 0 | N81: =IF(AND(G81="Paid",J81=0),"Paid, no payment",IF(AND(OR(G81="Failed",G81="Cancelled"),J81>0),"Payment on failed/cancelled",IF(J81>1,"Duplicate charge",IF(AND(J81=1,ROUND(K81-H81,2)<>0),"Amount difference",IF(AND(G81="Refunded",L81=0),"Refunded, no refund",IF(AND(G81<>"Refunded",L81>0),"Refund, order not Refunded",IF(AND(L81>0,ROUND(M81-H81,2)<>0),"Refund amount differs","OK"))))))) -> OK | O81: =IF(N81="OK",0,IF(N81="Paid, no payment",H81,IF(N81="Payment on failed/cancelled",K81,IF(OR(N81="Duplicate charge",N81="Amount difference"),K81-H81,IF(N81="Refunded, no refund",H81,M81))))) -> 0
A82: ORD26000081 | B82: 46292 | C82: CUST45992 | D82: Ahmedabad | E82: Card | F82: 10797.0 | G82: Paid | H82: =VALUE(SUBSTITUTE(F82,",","")) -> 10797 | I82: =IF(TRIM(D82)="","Unknown",TRIM(D82)) -> Ahmedabad | J82: =COUNTIFS(pg_transaction_cleaned!$O:$O,A82,pg_transaction_cleaned!$F:$F,"CAPTURE") -> 1 | K82: =SUMIFS(pg_transaction_cleaned!$H:$H,pg_transaction_cleaned!$O:$O,A82,pg_transaction_cleaned!$F:$F,"CAPTURE") -> 10797 | L82: =COUNTIFS(pg_transaction_cleaned!$O:$O,A82,pg_transaction_cleaned!$F:$F,"REFUND") -> 0 | M82: =SUMIFS(pg_transaction_cleaned!$H:$H,pg_transaction_cleaned!$O:$O,A82,pg_transaction_cleaned!$F:$F,"REFUND") -> 0 | N82: =IF(AND(G82="Paid",J82=0),"Paid, no payment",IF(AND(OR(G82="Failed",G82="Cancelled"),J82>0),"Payment on failed/cancelled",IF(J82>1,"Duplicate charge",IF(AND(J82=1,ROUND(K82-H82,2)<>0),"Amount difference",IF(AND(G82="Refunded",L82=0),"Refunded, no refund",IF(AND(G82<>"Refunded",L82>0),"Refund, order not Refunded",IF(AND(L82>0,ROUND(M82-H82,2)<>0),"Refund amount differs","OK"))))))) -> OK | O82: =IF(N82="OK",0,IF(N82="Paid, no payment",H82,IF(N82="Payment on failed/cancelled",K82,IF(OR(N82="Duplicate charge",N82="Amount difference"),K82-H82,IF(N82="Refunded, no refund",H82,M82))))) -> 0
A83: ORD26000082 | B83: 46268 | C83: CUST20561 | D83: Delhi | E83: Wallet | F83: 2197.0 | G83: Paid | H83: =VALUE(SUBSTITUTE(F83,",","")) -> 2197 | I83: =IF(TRIM(D83)="","Unknown",TRIM(D83)) -> Delhi | J83: =COUNTIFS(pg_transaction_cleaned!$O:$O,A83,pg_transaction_cleaned!$F:$F,"CAPTURE") -> 1 | K83: =SUMIFS(pg_transaction_cleaned!$H:$H,pg_transaction_cleaned!$O:$O,A83,pg_transaction_cleaned!$F:$F,"CAPTURE") -> 2197 | L83: =COUNTIFS(pg_transaction_cleaned!$O:$O,A83,pg_transaction_cleaned!$F:$F,"REFUND") -> 0 | M83: =SUMIFS(pg_transaction_cleaned!$H:$H,pg_transaction_cleaned!$O:$O,A83,pg_transaction_cleaned!$F:$F,"REFUND") -> 0 | N83: =IF(AND(G83="Paid",J83=0),"Paid, no payment",IF(AND(OR(G83="Failed",G83="Cancelled"),J83>0),"Payment on failed/cancelled",IF(J83>1,"Duplicate charge",IF(AND(J83=1,ROUND(K83-H83,2)<>0),"Amount difference",IF(AND(G83="Refunded",L83=0),"Refunded, no refund",IF(AND(G83<>"Refunded",L83>0),"Refund, order not Refunded",IF(AND(L83>0,ROUND(M83-H83,2)<>0),"Refund amount differs","OK"))))))) -> OK | O83: =IF(N83="OK",0,IF(N83="Paid, no payment",H83,IF(N83="Payment on failed/cancelled",K83,IF(OR(N83="Duplicate charge",N83="Amount difference"),K83-H83,IF(N83="Refunded, no refund",H83,M83))))) -> 0
A84: ORD26000083 | B84: 46270 | C84: CUST18418 | D84: Kolkata | E84: Card | F84: 1299.0 | G84: Paid | H84: =VALUE(SUBSTITUTE(F84,",","")) -> 1299 | I84: =IF(TRIM(D84)="","Unknown",TRIM(D84)) -> Kolkata | J84: =COUNTIFS(pg_transaction_cleaned!$O:$O,A84,pg_transaction_cleaned!$F:$F,"CAPTURE") -> 1 | K84: =SUMIFS(pg_transaction_cleaned!$H:$H,pg_transaction_cleaned!$O:$O,A84,pg_transaction_cleaned!$F:$F,"CAPTURE") -> 1299 | L84: =COUNTIFS(pg_transaction_cleaned!$O:$O,A84,pg_transaction_cleaned!$F:$F,"REFUND") -> 0 | M84: =SUMIFS(pg_transaction_cleaned!$H:$H,pg_transaction_cleaned!$O:$O,A84,pg_transaction_cleaned!$F:$F,"REFUND") -> 0 | N84: =IF(AND(G84="Paid",J84=0),"Paid, no payment",IF(AND(OR(G84="Failed",G84="Cancelled"),J84>0),"Payment on failed/cancelled",IF(J84>1,"Duplicate charge",IF(AND(J84=1,ROUND(K84-H84,2)<>0),"Amount difference",IF(AND(G84="Refunded",L84=0),"Refunded, no refund",IF(AND(G84<>"Refunded",L84>0),"Refund, order not Refunded",IF(AND(L84>0,ROUND(M84-H84,2)<>0),"Refund amount differs","OK"))))))) -> OK | O84: =IF(N84="OK",0,IF(N84="Paid, no payment",H84,IF(N84="Payment on failed/cancelled",K84,IF(OR(N84="Duplicate charge",N84="Amount difference"),K84-H84,IF(N84="Refunded, no refund",H84,M84))))) -> 0
A85: ORD26000084 | B85: 46279 | C85: CUST65069 | D85: Kolkata | E85: UPI | F85: 1799.0 | G85: Paid | H85: =VALUE(SUBSTITUTE(F85,",","")) -> 1799 | I85: =IF(TRIM(D85)="","Unknown",TRIM(D85)) -> Kolkata | J85: =COUNTIFS(pg_transaction_cleaned!$O:$O,A85,pg_transaction_cleaned!$F:$F,"CAPTURE") -> 1 | K85: =SUMIFS(pg_transaction_cleaned!$H:$H,pg_transaction_cleaned!$O:$O,A85,pg_transaction_cleaned!$F:$F,"CAPTURE") -> 1799 | L85: =COUNTIFS(pg_transaction_cleaned!$O:$O,A85,pg_transaction_cleaned!$F:$F,"REFUND") -> 0 | M85: =SUMIFS(pg_transaction_cleaned!$H:$H,pg_transaction_cleaned!$O:$O,A85,pg_transaction_cleaned!$F:$F,"REFUND") -> 0 | N85: =IF(AND(G85="Paid",J85=0),"Paid, no payment",IF(AND(OR(G85="Failed",G85="Cancelled"),J85>0),"Payment on failed/cancelled",IF(J85>1,"Duplicate charge",IF(AND(J85=1,ROUND(K85-H85,2)<>0),"Amount difference",IF(AND(G85="Refunded",L85=0),"Refunded, no refund",IF(AND(G85<>"Refunded",L85>0),"Refund, order not Refunded",IF(AND(L85>0,ROUND(M85-H85,2)<>0),"Refund amount differs","OK"))))))) -> OK | O85: =IF(N85="OK",0,IF(N85="Paid, no payment",H85,IF(N85="Payment on failed/cancelled",K85,IF(OR(N85="Duplicate charge",N85="Amount difference"),K85-H85,IF(N85="Refunded, no refund",H85,M85))))) -> 0
A86: ORD26000085 | B86: 46294 | C86: CUST59857 | D86: Ahmedabad | E86: Card | F86: 3798.0 | G86: Paid | H86: =VALUE(SUBSTITUTE(F86,",","")) -> 3798 | I86: =IF(TRIM(D86)="","Unknown",TRIM(D86)) -> Ahmedabad | J86: =COUNTIFS(pg_transaction_cleaned!$O:$O,A86,pg_transaction_cleaned!$F:$F,"CAPTURE") -> 1 | K86: =SUMIFS(pg_transaction_cleaned!$H:$H,pg_transaction_cleaned!$O:$O,A86,pg_transaction_cleaned!$F:$F,"CAPTURE") -> 3798 | L86: =COUNTIFS(pg_transaction_cleaned!$O:$O,A86,pg_transaction_cleaned!$F:$F,"REFUND") -> 0 | M86: =SUMIFS(pg_transaction_cleaned!$H:$H,pg_transaction_cleaned!$O:$O,A86,pg_transaction_cleaned!$F:$F,"REFUND") -> 0 | N86: =IF(AND(G86="Paid",J86=0),"Paid, no payment",IF(AND(OR(G86="Failed",G86="Cancelled"),J86>0),"Payment on failed/cancelled",IF(J86>1,"Duplicate charge",IF(AND(J86=1,ROUND(K86-H86,2)<>0),"Amount difference",IF(AND(G86="Refunded",L86=0),"Refunded, no refund",IF(AND(G86<>"Refunded",L86>0),"Refund, order not Refunded",IF(AND(L86>0,ROUND(M86-H86,2)<>0),"Refund amount differs","OK"))))))) -> OK | O86: =IF(N86="OK",0,IF(N86="Paid, no payment",H86,IF(N86="Payment on failed/cancelled",K86,IF(OR(N86="Duplicate charge",N86="Amount difference"),K86-H86,IF(N86="Refunded, no refund",H86,M86))))) -> 0
A87: ORD26000086 | B87: 46266 | C87: CUST64921 | D87: Jaipur | E87: NetBanking | F87: 799.0 | G87: Paid | H87: =VALUE(SUBSTITUTE(F87,",","")) -> 799 | I87: =IF(TRIM(D87)="","Unknown",TRIM(D87)) -> Jaipur | J87: =COUNTIFS(pg_transaction_cleaned!$O:$O,A87,pg_transaction_cleaned!$F:$F,"CAPTURE") -> 1 | K87: =SUMIFS(pg_transaction_cleaned!$H:$H,pg_transaction_cleaned!$O:$O,A87,pg_transaction_cleaned!$F:$F,"CAPTURE") -> 799 | L87: =COUNTIFS(pg_transaction_cleaned!$O:$O,A87,pg_transaction_cleaned!$F:$F,"REFUND") -> 0 | M87: =SUMIFS(pg_transaction_cleaned!$H:$H,pg_transaction_cleaned!$O:$O,A87,pg_transaction_cleaned!$F:$F,"REFUND") -> 0 | N87: =IF(AND(G87="Paid",J87=0),"Paid, no payment",IF(AND(OR(G87="Failed",G87="Cancelled"),J87>0),"Payment on failed/cancelled",IF(J87>1,"Duplicate charge",IF(AND(J87=1,ROUND(K87-H87,2)<>0),"Amount difference",IF(AND(G87="Refunded",L87=0),"Refunded, no refund",IF(AND(G87<>"Refunded",L87>0),"Refund, order not Refunded",IF(AND(L87>0,ROUND(M87-H87,2)<>0),"Refund amount differs","OK"))))))) -> OK | O87: =IF(N87="OK",0,IF(N87="Paid, no payment",H87,IF(N87="Payment on failed/cancelled",K87,IF(OR(N87="Duplicate charge",N87="Amount difference"),K87-H87,IF(N87="Refunded, no refund",H87,M87))))) -> 0
A88: ORD26000087 | B88: 46289 | C88: CUST45774 | D88: Kolkata | E88: UPI | F88: 9297.0 | G88: Failed | H88: =VALUE(SUBSTITUTE(F88,",","")) -> 9297 | I88: =IF(TRIM(D88)="","Unknown",TRIM(D88)) -> Kolkata | J88: =COUNTIFS(pg_transaction_cleaned!$O:$O,A88,pg_transaction_cleaned!$F:$F,"CAPTURE") -> 0 | K88: =SUMIFS(pg_transaction_cleaned!$H:$H,pg_transaction_cleaned!$O:$O,A88,pg_transaction_cleaned!$F:$F,"CAPTURE") -> 0 | L88: =COUNTIFS(pg_transaction_cleaned!$O:$O,A88,pg_transaction_cleaned!$F:$F,"REFUND") -> 0 | M88: =SUMIFS(pg_transaction_cleaned!$H:$H,pg_transaction_cleaned!$O:$O,A88,pg_transaction_cleaned!$F:$F,"REFUND") -> 0 | N88: =IF(AND(G88="Paid",J88=0),"Paid, no payment",IF(AND(OR(G88="Failed",G88="Cancelled"),J88>0),"Payment on failed/cancelled",IF(J88>1,"Duplicate charge",IF(AND(J88=1,ROUND(K88-H88,2)<>0),"Amount difference",IF(AND(G88="Refunded",L88=0),"Refunded, no refund",IF(AND(G88<>"Refunded",L88>0),"Refund, order not Refunded",IF(AND(L88>0,ROUND(M88-H88,2)<>0),"Refund amount differs","OK"))))))) -> OK | O88: =IF(N88="OK",0,IF(N88="Paid, no payment",H88,IF(N88="Payment on failed/cancelled",K88,IF(OR(N88="Duplicate charge",N88="Amount difference"),K88-H88,IF(N88="Refunded, no refund",H88,M88))))) -> 0
A89: ORD26000088 | B89: 46281 | C89: CUST62994 | D89: Delhi | E89: Card | F89: 1299.0 | G89: Paid | H89: =VALUE(SUBSTITUTE(F89,",","")) -> 1299 | I89: =IF(TRIM(D89)="","Unknown",TRIM(D89)) -> Delhi | J89: =COUNTIFS(pg_transaction_cleaned!$O:$O,A89,pg_transaction_cleaned!$F:$F,"CAPTURE") -> 1 | K89: =SUMIFS(pg_transaction_cleaned!$H:$H,pg_transaction_cleaned!$O:$O,A89,pg_transaction_cleaned!$F:$F,"CAPTURE") -> 1299 | L89: =COUNTIFS(pg_transaction_cleaned!$O:$O,A89,pg_transaction_cleaned!$F:$F,"REFUND") -> 0 | M89: =SUMIFS(pg_transaction_cleaned!$H:$H,pg_transaction_cleaned!$O:$O,A89,pg_transaction_cleaned!$F:$F,"REFUND") -> 0 | N89: =IF(AND(G89="Paid",J89=0),"Paid, no payment",IF(AND(OR(G89="Failed",G89="Cancelled"),J89>0),"Payment on failed/cancelled",IF(J89>1,"Duplicate charge",IF(AND(J89=1,ROUND(K89-H89,2)<>0),"Amount difference",IF(AND(G89="Refunded",L89=0),"Refunded, no refund",IF(AND(G89<>"Refunded",L89>0),"Refund, order not Refunded",IF(AND(L89>0,ROUND(M89-H89,2)<>0),"Refund amount differs","OK"))))))) -> OK | O89: =IF(N89="OK",0,IF(N89="Paid, no payment",H89,IF(N89="Payment on failed/cancelled",K89,IF(OR(N89="Duplicate charge",N89="Amount difference"),K89-H89,IF(N89="Refunded, no refund",H89,M89))))) -> 0
A90: ORD26000089 | B90: 46292 | C90: CUST87580 | D90: Lucknow | E90: Wallet | F90: 2998.0 | G90: Paid | H90: =VALUE(SUBSTITUTE(F90,",","")) -> 2998 | I90: =IF(TRIM(D90)="","Unknown",TRIM(D90)) -> Lucknow | J90: =COUNTIFS(pg_transaction_cleaned!$O:$O,A90,pg_transaction_cleaned!$F:$F,"CAPTURE") -> 1 | K90: =SUMIFS(pg_transaction_cleaned!$H:$H,pg_transaction_cleaned!$O:$O,A90,pg_transaction_cleaned!$F:$F,"CAPTURE") -> 2998 | L90: =COUNTIFS(pg_transaction_cleaned!$O:$O,A90,pg_transaction_cleaned!$F:$F,"REFUND") -> 0 | M90: =SUMIFS(pg_transaction_cleaned!$H:$H,pg_transaction_cleaned!$O:$O,A90,pg_transaction_cleaned!$F:$F,"REFUND") -> 0 | N90: =IF(AND(G90="Paid",J90=0),"Paid, no payment",IF(AND(OR(G90="Failed",G90="Cancelled"),J90>0),"Payment on failed/cancelled",IF(J90>1,"Duplicate charge",IF(AND(J90=1,ROUND(K90-H90,2)<>0),"Amount difference",IF(AND(G90="Refunded",L90=0),"Refunded, no refund",IF(AND(G90<>"Refunded",L90>0),"Refund, order not Refunded",IF(AND(L90>0,ROUND(M90-H90,2)<>0),"Refund amount differs","OK"))))))) -> OK | O90: =IF(N90="OK",0,IF(N90="Paid, no payment",H90,IF(N90="Payment on failed/cancelled",K90,IF(OR(N90="Duplicate charge",N90="Amount difference"),K90-H90,IF(N90="Refunded, no refund",H90,M90))))) -> 0
A91: ORD26000090 | B91: 46287 | C91: CUST70515 | D91: Delhi | E91: UPI | F91: 349.0 | G91: Paid | H91: =VALUE(SUBSTITUTE(F91,",","")) -> 349 | I91: =IF(TRIM(D91)="","Unknown",TRIM(D91)) -> Delhi | J91: =COUNTIFS(pg_transaction_cleaned!$O:$O,A91,pg_transaction_cleaned!$F:$F,"CAPTURE") -> 1 | K91: =SUMIFS(pg_transaction_cleaned!$H:$H,pg_transaction_cleaned!$O:$O,A91,pg_transaction_cleaned!$F:$F,"CAPTURE") -> 349 | L91: =COUNTIFS(pg_transaction_cleaned!$O:$O,A91,pg_transaction_cleaned!$F:$F,"REFUND") -> 0 | M91: =SUMIFS(pg_transaction_cleaned!$H:$H,pg_transaction_cleaned!$O:$O,A91,pg_transaction_cleaned!$F:$F,"REFUND") -> 0 | N91: =IF(AND(G91="Paid",J91=0),"Paid, no payment",IF(AND(OR(G91="Failed",G91="Cancelled"),J91>0),"Payment on failed/cancelled",IF(J91>1,"Duplicate charge",IF(AND(J91=1,ROUND(K91-H91,2)<>0),"Amount difference",IF(AND(G91="Refunded",L91=0),"Refunded, no refund",IF(AND(G91<>"Refunded",L91>0),"Refund, order not Refunded",IF(AND(L91>0,ROUND(M91-H91,2)<>0),"Refund amount differs","OK"))))))) -> OK | O91: =IF(N91="OK",0,IF(N91="Paid, no payment",H91,IF(N91="Payment on failed/cancelled",K91,IF(OR(N91="Duplicate charge",N91="Amount difference"),K91-H91,IF(N91="Refunded, no refund",H91,M91))))) -> 0
A92: ORD26000091 | B92: 46267 | C92: CUST54236 | D92: Kolkata | E92: UPI | F92: 1299.0 | G92: Paid | H92: =VALUE(SUBSTITUTE(F92,",","")) -> 1299 | I92: =IF(TRIM(D92)="","Unknown",TRIM(D92)) -> Kolkata | J92: =COUNTIFS(pg_transaction_cleaned!$O:$O,A92,pg_transaction_cleaned!$F:$F,"CAPTURE") -> 1 | K92: =SUMIFS(pg_transaction_cleaned!$H:$H,pg_transaction_cleaned!$O:$O,A92,pg_transaction_cleaned!$F:$F,"CAPTURE") -> 1299 | L92: =COUNTIFS(pg_transaction_cleaned!$O:$O,A92,pg_transaction_cleaned!$F:$F,"REFUND") -> 0 | M92: =SUMIFS(pg_transaction_cleaned!$H:$H,pg_transaction_cleaned!$O:$O,A92,pg_transaction_cleaned!$F:$F,"REFUND") -> 0 | N92: =IF(AND(G92="Paid",J92=0),"Paid, no payment",IF(AND(OR(G92="Failed",G92="Cancelled"),J92>0),"Payment on failed/cancelled",IF(J92>1,"Duplicate charge",IF(AND(J92=1,ROUND(K92-H92,2)<>0),"Amount difference",IF(AND(G92="Refunded",L92=0),"Refunded, no refund",IF(AND(G92<>"Refunded",L92>0),"Refund, order not Refunded",IF(AND(L92>0,ROUND(M92-H92,2)<>0),"Refund amount differs","OK"))))))) -> OK | O92: =IF(N92="OK",0,IF(N92="Paid, no payment",H92,IF(N92="Payment on failed/cancelled",K92,IF(OR(N92="Duplicate charge",N92="Amount difference"),K92-H92,IF(N92="Refunded, no refund",H92,M92))))) -> 0
A93: ORD26000092 | B93: 46274 | C93: CUST80702 | D93: Mumbai | E93: UPI | F93: 8798.0 | G93: Paid | H93: =VALUE(SUBSTITUTE(F93,",","")) -> 8798 | I93: =IF(TRIM(D93)="","Unknown",TRIM(D93)) -> Mumbai | J93: =COUNTIFS(pg_transaction_cleaned!$O:$O,A93,pg_transaction_cleaned!$F:$F,"CAPTURE") -> 1 | K93: =SUMIFS(pg_transaction_cleaned!$H:$H,pg_transaction_cleaned!$O:$O,A93,pg_transaction_cleaned!$F:$F,"CAPTURE") -> 8798 | L93: =COUNTIFS(pg_transaction_cleaned!$O:$O,A93,pg_transaction_cleaned!$F:$F,"REFUND") -> 0 | M93: =SUMIFS(pg_transaction_cleaned!$H:$H,pg_transaction_cleaned!$O:$O,A93,pg_transaction_cleaned!$F:$F,"REFUND") -> 0 | N93: =IF(AND(G93="Paid",J93=0),"Paid, no payment",IF(AND(OR(G93="Failed",G93="Cancelled"),J93>0),"Payment on failed/cancelled",IF(J93>1,"Duplicate charge",IF(AND(J93=1,ROUND(K93-H93,2)<>0),"Amount difference",IF(AND(G93="Refunded",L93=0),"Refunded, no refund",IF(AND(G93<>"Refunded",L93>0),"Refund, order not Refunded",IF(AND(L93>0,ROUND(M93-H93,2)<>0),"Refund amount differs","OK"))))))) -> OK | O93: =IF(N93="OK",0,IF(N93="Paid, no payment",H93,IF(N93="Payment on failed/cancelled",K93,IF(OR(N93="Duplicate charge",N93="Amount difference"),K93-H93,IF(N93="Refunded, no refund",H93,M93))))) -> 0
... A126: ORD26000125 | B126: 46269 | C126: CUST28643 | D126: Pune | E126: UPI | F126: 3598.0 | G126: Paid | H126: =VALUE(SUBSTITUTE(F126,",","")) -> 3598 | I126: =IF(TRIM(D126)="","Unknown",TRIM(D126)) -> Pune | J126: =COUNTIFS(pg_transaction_cleaned!$O:$O,A126,pg_transaction_cleaned!$F:$F,"CAPTURE") -> 1 | K126: =SUMIFS(pg_transaction_cleaned!$H:$H,pg_transaction_cleaned!$O:$O,A126,pg_transaction_cleaned!$F:$F,"CAPTURE") -> 3598 | L126: =COUNTIFS(pg_transaction_cleaned!$O:$O,A126,pg_transaction_cleaned!$F:$F,"REFUND") -> 0 | M126: =SUMIFS(pg_transaction_cleaned!$H:$H,pg_transaction_cleaned!$O:$O,A126,pg_transaction_cleaned!$F:$F,"REFUND") -> 0 | N126: =IF(AND(G126="Paid",J126=0),"Paid, no payment",IF(AND(OR(G126="Failed",G126="Cancelled"),J126>0),"Payment on failed/cancelled",IF(J126>1,"Duplicate charge",IF(AND(J126=1,ROUND(K126-H126,2)<>0),"Amount difference",IF(AND(G126="Refunded",L126=0),"Refunded, no refund",IF(AND(G126<>"Refunded",L126>0),"Refund, order not Refunded",IF(AND(L126>0,ROUND(M126-H126,2)<>0),"Refund amount differs","OK"))))))) -> OK | O126: =IF(N126="OK",0,IF(N126="Paid, no payment",H126,IF(N126="Payment on failed/cancelled",K126,IF(OR(N126="Duplicate charge",N126="Amount difference"),K126-H126,IF(N126="Refunded, no refund",H126,M126))))) -> 0
A127: ORD26000126 | B127: 46267 | C127: CUST84607 | E127: Card | F127: 4999.0 | G127: Paid | H127: =VALUE(SUBSTITUTE(F127,",","")) -> 4999 | I127: =IF(TRIM(D127)="","Unknown",TRIM(D127)) -> Unknown | J127: =COUNTIFS(pg_transaction_cleaned!$O:$O,A127,pg_transaction_cleaned!$F:$F,"CAPTURE") -> 1 | K127: =SUMIFS(pg_transaction_cleaned!$H:$H,pg_transaction_cleaned!$O:$O,A127,pg_transaction_cleaned!$F:$F,"CAPTURE") -> 4999 | L127: =COUNTIFS(pg_transaction_cleaned!$O:$O,A127,pg_transaction_cleaned!$F:$F,"REFUND") -> 0 | M127: =SUMIFS(pg_transaction_cleaned!$H:$H,pg_transaction_cleaned!$O:$O,A127,pg_transaction_cleaned!$F:$F,"REFUND") -> 0 | N127: =IF(AND(G127="Paid",J127=0),"Paid, no payment",IF(AND(OR(G127="Failed",G127="Cancelled"),J127>0),"Payment on failed/cancelled",IF(J127>1,"Duplicate charge",IF(AND(J127=1,ROUND(K127-H127,2)<>0),"Amount difference",IF(AND(G127="Refunded",L127=0),"Refunded, no refund",IF(AND(G127<>"Refunded",L127>0),"Refund, order not Refunded",IF(AND(L127>0,ROUND(M127-H127,2)<>0),"Refund amount differs","OK"))))))) -> OK | O127: =IF(N127="OK",0,IF(N127="Paid, no payment",H127,IF(N127="Payment on failed/cancelled",K127,IF(OR(N127="Duplicate charge",N127="Amount difference"),K127-H127,IF(N127="Refunded, no refund",H127,M127))))) -> 0
