Workbook

Sheet pg_transaction_cleaned
A1: pg_txn_id | B1: original_payment_id | C1: merchant_order_ref | D1: merchant_order_ref_changed | E1: txn_date | F1: txn_type | G1: payment_method | H1: gross_amount | I1: mdr_fee | J1: gst_on_fee | K1: net_amount | L1: settlement_date | M1: settlement_batch_id | N1: dup_flag | O1: order_key | P1: settlement_period
A2: pay_420000065 | C2: ORD26000066 | D2: =UPPER(SUBSTITUTE(TRIM(C2),"-","")) -> ORD26000066 | E2: 46266 | F2: CAPTURE | G2: Wallet | H2: 6798 | I2: 163.15 | J2: 29.37 | K2: 6605.48 | L2: 46268 | M2: STL-20260903 | N2: =IF(COUNTIF($A$2:A2,A2)>1,"DUP","OK") -> OK | O2: =IF(F2="REFUND",INDEX($D$2:$D$5743,MATCH(B2,$A$2:$A$5743,0)),D2) -> ORD26000066 | P2: =IF(L2>DATE(2026,9,30),"Oct-Due","Sep") -> Sep
A3: pay_420000121 | C3: ORD-26000130 | D3: =UPPER(SUBSTITUTE(TRIM(C3),"-","")) -> ORD26000130 | E3: 46266 | F3: CAPTURE | G3: Card | H3: 11297 | I3: 180.75 | J3: 32.54 | K3: 11083.71 | L3: 46268 | M3: STL-20260903 | N3: =IF(COUNTIF($A$2:A3,A3)>1,"DUP","OK") -> OK | O3: =IF(F3="REFUND",INDEX($D$2:$D$5743,MATCH(B3,$A$2:$A$5743,0)),D3) -> ORD26000130 | P3: =IF(L3>DATE(2026,9,30),"Oct-Due","Sep") -> Sep
A4: pay_420000170 | C4: ORD26000184 | D4: =UPPER(SUBSTITUTE(TRIM(C4),"-","")) -> ORD26000184 | E4: 46266 | F4: CAPTURE | G4: Card | H4: 4999 | I4: 79.98 | J4: 14.4 | K4: 4904.62 | L4: 46268 | M4: STL-20260903 | N4: =IF(COUNTIF($A$2:A4,A4)>1,"DUP","OK") -> OK | O4: =IF(F4="REFUND",INDEX($D$2:$D$5743,MATCH(B4,$A$2:$A$5743,0)),D4) -> ORD26000184 | P4: =IF(L4>DATE(2026,9,30),"Oct-Due","Sep") -> Sep
A5: pay_420000229 | C5: ORD26000244 | D5: =UPPER(SUBSTITUTE(TRIM(C5),"-","")) -> ORD26000244 | E5: 46266 | F5: CAPTURE | G5: Card | H5: 349 | I5: 6.28 | J5: 1.13 | K5: 341.59 | L5: 46268 | M5: STL-20260903 | N5: =IF(COUNTIF($A$2:A5,A5)>1,"DUP","OK") -> OK | O5: =IF(F5="REFUND",INDEX($D$2:$D$5743,MATCH(B5,$A$2:$A$5743,0)),D5) -> ORD26000244 | P5: =IF(L5>DATE(2026,9,30),"Oct-Due","Sep") -> Sep
A6: pay_420000236 | C6: ORD26000252 | D6: =UPPER(SUBSTITUTE(TRIM(C6),"-","")) -> ORD26000252 | E6: 46266 | F6: CAPTURE | G6: UPI | H6: 9498 | I6: 28.49 | J6: 5.13 | K6: 9464.38 | L6: 46268 | M6: STL-20260903 | N6: =IF(COUNTIF($A$2:A6,A6)>1,"DUP","OK") -> OK | O6: =IF(F6="REFUND",INDEX($D$2:$D$5743,MATCH(B6,$A$2:$A$5743,0)),D6) -> ORD26000252 | P6: =IF(L6>DATE(2026,9,30),"Oct-Due","Sep") -> Sep
A7: pay_420000249 | C7: ORD26000266 | D7: =UPPER(SUBSTITUTE(TRIM(C7),"-","")) -> ORD26000266 | E7: 46266 | F7: CAPTURE | G7: Card | H7: 7999 | I7: 127.98 | J7: 23.04 | K7: 7847.98 | L7: 46268 | M7: STL-20260903 | N7: =IF(COUNTIF($A$2:A7,A7)>1,"DUP","OK") -> OK | O7: =IF(F7="REFUND",INDEX($D$2:$D$5743,MATCH(B7,$A$2:$A$5743,0)),D7) -> ORD26000266 | P7: =IF(L7>DATE(2026,9,30),"Oct-Due","Sep") -> Sep
A8: pay_420000316 | C8: ORD26000331 | D8: =UPPER(SUBSTITUTE(TRIM(C8),"-","")) -> ORD26000331 | E8: 46266 | F8: CAPTURE | G8: Card | H8: 1299 | I8: 23.38 | J8: 4.21 | K8: 1271.41 | L8: 46268 | M8: STL-20260903 | N8: =IF(COUNTIF($A$2:A8,A8)>1,"DUP","OK") -> OK | O8: =IF(F8="REFUND",INDEX($D$2:$D$5743,MATCH(B8,$A$2:$A$5743,0)),D8) -> ORD26000331 | P8: =IF(L8>DATE(2026,9,30),"Oct-Due","Sep") -> Sep
A9: pay_420000355 | C9: ORD26000373 | D9: =UPPER(SUBSTITUTE(TRIM(C9),"-","")) -> ORD26000373 | E9: 46266 | F9: CAPTURE | G9: UPI | H9: 1799 | I9: 0 | J9: 0 | K9: 1799 | L9: 46268 | M9: STL-20260903 | N9: =IF(COUNTIF($A$2:A9,A9)>1,"DUP","OK") -> OK | O9: =IF(F9="REFUND",INDEX($D$2:$D$5743,MATCH(B9,$A$2:$A$5743,0)),D9) -> ORD26000373 | P9: =IF(L9>DATE(2026,9,30),"Oct-Due","Sep") -> Sep
A10: pay_420000357 | C10: ORD26000375 | D10: =UPPER(SUBSTITUTE(TRIM(C10),"-","")) -> ORD26000375 | E10: 46266 | F10: CAPTURE | G10: UPI | H10: 4298 | I10: 12.89 | J10: 2.32 | K10: 4282.79 | L10: 46268 | M10: STL-20260903 | N10: =IF(COUNTIF($A$2:A10,A10)>1,"DUP","OK") -> OK | O10: =IF(F10="REFUND",INDEX($D$2:$D$5743,MATCH(B10,$A$2:$A$5743,0)),D10) -> ORD26000375 | P10: =IF(L10>DATE(2026,9,30),"Oct-Due","Sep") -> Sep
A11: pay_420000392 | C11: ORD26000410 | D11: =UPPER(SUBSTITUTE(TRIM(C11),"-","")) -> ORD26000410 | E11: 46266 | F11: CAPTURE | G11: Card | H11: 799 | I11: 14.38 | J11: 2.59 | K11: 782.03 | L11: 46268 | M11: STL-20260903 | N11: =IF(COUNTIF($A$2:A11,A11)>1,"DUP","OK") -> OK | O11: =IF(F11="REFUND",INDEX($D$2:$D$5743,MATCH(B11,$A$2:$A$5743,0)),D11) -> ORD26000410 | P11: =IF(L11>DATE(2026,9,30),"Oct-Due","Sep") -> Sep
A12: pay_420000449 | C12: ORD26000470 | D12: =UPPER(SUBSTITUTE(TRIM(C12),"-","")) -> ORD26000470 | E12: 46266 | F12: CAPTURE | G12: Wallet | H12: 4297 | I12: 73.05 | J12: 13.15 | K12: 4210.8 | L12: 46268 | M12: STL-20260903 | N12: =IF(COUNTIF($A$2:A12,A12)>1,"DUP","OK") -> OK | O12: =IF(F12="REFUND",INDEX($D$2:$D$5743,MATCH(B12,$A$2:$A$5743,0)),D12) -> ORD26000470 | P12: =IF(L12>DATE(2026,9,30),"Oct-Due","Sep") -> Sep
A13: pay_420000460 | C13: ORD26000483 | D13: =UPPER(SUBSTITUTE(TRIM(C13),"-","")) -> ORD26000483 | E13: 46266 | F13: CAPTURE | G13: Card | H13: 898 | I13: 16.16 | J13: 2.91 | K13: 878.93 | L13: 46268 | M13: STL-20260903 | N13: =IF(COUNTIF($A$2:A13,A13)>1,"DUP","OK") -> OK | O13: =IF(F13="REFUND",INDEX($D$2:$D$5743,MATCH(B13,$A$2:$A$5743,0)),D13) -> ORD26000483 | P13: =IF(L13>DATE(2026,9,30),"Oct-Due","Sep") -> Sep
... A329: pay_420005677 | C329: ORD26005942 | D329: =UPPER(SUBSTITUTE(TRIM(C329),"-","")) -> ORD26005942 | E329: 46267 | F329: CAPTURE | G329: Wallet | H329: 1499 | I329: 28.48 | J329: 5.13 | K329: 1465.39 | L329: 46269 | M329: STL-20260904 | N329: =IF(COUNTIF($A$2:A329,A329)>1,"DUP","OK") -> OK | O329: =IF(F329="REFUND",INDEX($D$2:$D$5743,MATCH(B329,$A$2:$A$5743,0)),D329) -> ORD26005942 | P329: =IF(L329>DATE(2026,9,30),"Oct-Due","Sep") -> Sep
A330: rfnd_BDDX8L3AAXM0 | B330: pay_420002554 | D330: =UPPER(SUBSTITUTE(TRIM(C330),"-","")) | E330: 46267 | F330: REFUND | G330: Wallet | H330: 1799 | I330: 0 | J330: 0 | K330: -1799 | L330: 46269 | M330: STL-20260904 | N330: =IF(COUNTIF($A$2:A330,A330)>1,"DUP","OK") -> OK | O330: =IF(F330="REFUND",INDEX($D$2:$D$5743,MATCH(B330,$A$2:$A$5743,0)),D330) -> ORD26002680 | P330: =IF(L330>DATE(2026,9,30),"Oct-Due","Sep") -> Sep
A331: rfnd_W6UU5WJWSTPB | B331: pay_420004896 | D331: =UPPER(SUBSTITUTE(TRIM(C331),"-","")) | E331: 46267 | F331: REFUND | G331: NetBanking | H331: 599 | I331: 0 | J331: 0 | K331: -599 | L331: 46269 | M331: STL-20260904 | N331: =IF(COUNTIF($A$2:A331,A331)>1,"DUP","OK") -> OK | O331: =IF(F331="REFUND",INDEX($D$2:$D$5743,MATCH(B331,$A$2:$A$5743,0)),D331) -> ORD26005124 | P331: =IF(L331>DATE(2026,9,30),"Oct-Due","Sep") -> Sep
A332: pay_420000041 | C332: ORD26000042 | D332: =UPPER(SUBSTITUTE(TRIM(C332),"-","")) -> ORD26000042 | E332: 46268 | F332: CAPTURE | G332: Card | H332: 349 | I332: 6.28 | J332: 1.13 | K332: 341.59 | L332: 46270 | M332: STL-20260905 | N332: =IF(COUNTIF($A$2:A332,A332)>1,"DUP","OK") -> OK | O332: =IF(F332="REFUND",INDEX($D$2:$D$5743,MATCH(B332,$A$2:$A$5743,0)),D332) -> ORD26000042 | P332: =IF(L332>DATE(2026,9,30),"Oct-Due","Sep") -> Sep
A333: pay_420000078 | C333: ORD26000082 | D333: =UPPER(SUBSTITUTE(TRIM(C333),"-","")) -> ORD26000082 | E333: 46268 | F333: CAPTURE | G333: Wallet | H333: 2197 | I333: 37.35 | J333: 6.72 | K333: 2152.93 | L333: 46270 | M333: STL-20260905 | N333: =IF(COUNTIF($A$2:A333,A333)>1,"DUP","OK") -> OK | O333: =IF(F333="REFUND",INDEX($D$2:$D$5743,MATCH(B333,$A$2:$A$5743,0)),D333) -> ORD26000082 | P333: =IF(L333>DATE(2026,9,30),"Oct-Due","Sep") -> Sep
A334: pay_420000101 | C334: ORD26000109 | D334: =UPPER(SUBSTITUTE(TRIM(C334),"-","")) -> ORD26000109 | E334: 46268 | F334: CAPTURE | G334: UPI | H334: 599 | I334: 0 | J334: 0 | K334: 599 | L334: 46270 | M334: STL-20260905 | N334: =IF(COUNTIF($A$2:A334,A334)>1,"DUP","OK") -> OK | O334: =IF(F334="REFUND",INDEX($D$2:$D$5743,MATCH(B334,$A$2:$A$5743,0)),D334) -> ORD26000109 | P334: =IF(L334>DATE(2026,9,30),"Oct-Due","Sep") -> Sep
A335: pay_420000111 | C335: ORD26000119 | D335: =UPPER(SUBSTITUTE(TRIM(C335),"-","")) -> ORD26000119 | E335: 46268 | F335: CAPTURE | G335: UPI | H335: 349 | I335: 0 | J335: 0 | K335: 349 | L335: 46270 | M335: STL-20260905 | N335: =IF(COUNTIF($A$2:A335,A335)>1,"DUP","OK") -> OK | O335: =IF(F335="REFUND",INDEX($D$2:$D$5743,MATCH(B335,$A$2:$A$5743,0)),D335) -> ORD26000119 | P335: =IF(L335>DATE(2026,9,30),"Oct-Due","Sep") -> Sep
A336: pay_420000115 | C336: ORD26000124 | D336: =UPPER(SUBSTITUTE(TRIM(C336),"-","")) -> ORD26000124 | E336: 46268 | F336: CAPTURE | G336: Card | H336: 6397 | I336: 102.35 | J336: 18.42 | K336: 6276.23 | L336: 46270 | M336: STL-20260905 | N336: =IF(COUNTIF($A$2:A336,A336)>1,"DUP","OK") -> OK | O336: =IF(F336="REFUND",INDEX($D$2:$D$5743,MATCH(B336,$A$2:$A$5743,0)),D336) -> ORD26000124 | P336: =IF(L336>DATE(2026,9,30),"Oct-Due","Sep") -> Sep
A337: pay_420000228 | C337: ORD26000243 | D337: =UPPER(SUBSTITUTE(TRIM(C337),"-","")) -> ORD26000243 | E337: 46268 | F337: CAPTURE | G337: Wallet | H337: 2798 | I337: 47.57 | J337: 8.56 | K337: 2741.87 | L337: 46270 | M337: STL-20260905 | N337: =IF(COUNTIF($A$2:A337,A337)>1,"DUP","OK") -> OK | O337: =IF(F337="REFUND",INDEX($D$2:$D$5743,MATCH(B337,$A$2:$A$5743,0)),D337) -> ORD26000243 | P337: =IF(L337>DATE(2026,9,30),"Oct-Due","Sep") -> Sep
A338: pay_420000250 | C338: ORD26000267 | D338: =UPPER(SUBSTITUTE(TRIM(C338),"-","")) -> ORD26000267 | E338: 46268 | F338: CAPTURE | G338: UPI | H338: 4999 | I338: 15 | J338: 2.7 | K338: 4981.3 | L338: 46270 | M338: STL-20260905 | N338: =IF(COUNTIF($A$2:A338,A338)>1,"DUP","OK") -> OK | O338: =IF(F338="REFUND",INDEX($D$2:$D$5743,MATCH(B338,$A$2:$A$5743,0)),D338) -> ORD26000267 | P338: =IF(L338>DATE(2026,9,30),"Oct-Due","Sep") -> Sep
A339: pay_420000268 | C339: ORD26000285 | D339: =UPPER(SUBSTITUTE(TRIM(C339),"-","")) -> ORD26000285 | E339: 46268 | F339: CAPTURE | G339: Card | H339: 349 | I339: 6.28 | J339: 1.13 | K339: 341.59 | L339: 46270 | M339: STL-20260905 | N339: =IF(COUNTIF($A$2:A339,A339)>1,"DUP","OK") -> OK | O339: =IF(F339="REFUND",INDEX($D$2:$D$5743,MATCH(B339,$A$2:$A$5743,0)),D339) -> ORD26000285 | P339: =IF(L339>DATE(2026,9,30),"Oct-Due","Sep") -> Sep
A340: pay_420000281 | C340: ord26000298 | D340: =UPPER(SUBSTITUTE(TRIM(C340),"-","")) -> ORD26000298 | E340: 46268 | F340: CAPTURE | G340: UPI | H340: 2398 | I340: 7.19 | J340: 1.29 | K340: 2389.52 | L340: 46270 | M340: STL-20260905 | N340: =IF(COUNTIF($A$2:A340,A340)>1,"DUP","OK") -> OK | O340: =IF(F340="REFUND",INDEX($D$2:$D$5743,MATCH(B340,$A$2:$A$5743,0)),D340) -> ORD26000298 | P340: =IF(L340>DATE(2026,9,30),"Oct-Due","Sep") -> Sep
A341: pay_420000315 | C341: ORD26000330 | D341: =UPPER(SUBSTITUTE(TRIM(C341),"-","")) -> ORD26000330 | E341: 46268 | F341: CAPTURE | G341: UPI | H341: 3348 | I341: 10.04 | J341: 1.81 | K341: 3336.15 | L341: 46270 | M341: STL-20260905 | N341: =IF(COUNTIF($A$2:A341,A341)>1,"DUP","OK") -> OK | O341: =IF(F341="REFUND",INDEX($D$2:$D$5743,MATCH(B341,$A$2:$A$5743,0)),D341) -> ORD26000330 | P341: =IF(L341>DATE(2026,9,30),"Oct-Due","Sep") -> Sep
A342: pay_420000430 | C342: ORD26000447 | D342: =UPPER(SUBSTITUTE(TRIM(C342),"-","")) -> ORD26000447 | E342: 46268 | F342: CAPTURE | G342: UPI | H342: 2999 | I342: 9 | J342: 1.62 | K342: 2988.38 | L342: 46270 | M342: STL-20260905 | N342: =IF(COUNTIF($A$2:A342,A342)>1,"DUP","OK") -> OK | O342: =IF(F342="REFUND",INDEX($D$2:$D$5743,MATCH(B342,$A$2:$A$5743,0)),D342) -> ORD26000447 | P342: =IF(L342>DATE(2026,9,30),"Oct-Due","Sep") -> Sep
A343: pay_420000437 | C343: ord26000455 | D343: =UPPER(SUBSTITUTE(TRIM(C343),"-","")) -> ORD26000455 | E343: 46268 | F343: CAPTURE | G343: UPI | H343: 2798 | I343: 8.39 | J343: 1.51 | K343: 2788.1 | L343: 46270 | M343: STL-20260905 | N343: =IF(COUNTIF($A$2:A343,A343)>1,"DUP","OK") -> OK | O343: =IF(F343="REFUND",INDEX($D$2:$D$5743,MATCH(B343,$A$2:$A$5743,0)),D343) -> ORD26000455 | P343: =IF(L343>DATE(2026,9,30),"Oct-Due","Sep") -> Sep
... A519: pay_420005699 | C519: ORD26005966 | D519: =UPPER(SUBSTITUTE(TRIM(C519),"-","")) -> ORD26005966 | E519: 46268 | F519: CAPTURE | G519: UPI | H519: 2798 | I519: 8.39 | J519: 1.51 | K519: 2788.1 | L519: 46270 | M519: STL-20260905 | N519: =IF(COUNTIF($A$2:A519,A519)>1,"DUP","OK") -> OK | O519: =IF(F519="REFUND",INDEX($D$2:$D$5743,MATCH(B519,$A$2:$A$5743,0)),D519) -> ORD26005966 | P519: =IF(L519>DATE(2026,9,30),"Oct-Due","Sep") -> Sep
A520: rfnd_1C41Q7T6GFAL | B520: pay_420001351 | D520: =UPPER(SUBSTITUTE(TRIM(C520),"-","")) | E520: 46268 | F520: REFUND | G520: Card | H520: 9297 | I520: 0 | J520: 0 | K520: -9297 | L520: 46270 | M520: STL-20260905 | N520: =IF(COUNTIF($A$2:A520,A520)>1,"DUP","OK") -> OK | O520: =IF(F520="REFUND",INDEX($D$2:$D$5743,MATCH(B520,$A$2:$A$5743,0)),D520) -> ORD26001416 | P520: =IF(L520>DATE(2026,9,30),"Oct-Due","Sep") -> Sep
A521: rfnd_KJKJAE6PT0EL | B521: pay_420003553 | D521: =UPPER(SUBSTITUTE(TRIM(C521),"-","")) | E521: 46268 | F521: REFUND | G521: UPI | H521: 2499 | I521: 0 | J521: 0 | K521: -2499 | L521: 46270 | M521: STL-20260905 | N521: =IF(COUNTIF($A$2:A521,A521)>1,"DUP","OK") -> OK | O521: =IF(F521="REFUND",INDEX($D$2:$D$5743,MATCH(B521,$A$2:$A$5743,0)),D521) -> ORD26003723 | P521: =IF(L521>DATE(2026,9,30),"Oct-Due","Sep") -> Sep
A522: pay_420000042 | C522: ORD26000043 | D522: =UPPER(SUBSTITUTE(TRIM(C522),"-","")) -> ORD26000043 | E522: 46269 | F522: CAPTURE | G522: Card | H522: 3098 | I522: 49.57 | J522: 8.92 | K522: 3039.51 | L522: 46271 | M522: STL-20260906 | N522: =IF(COUNTIF($A$2:A522,A522)>1,"DUP","OK") -> OK | O522: =IF(F522="REFUND",INDEX($D$2:$D$5743,MATCH(B522,$A$2:$A$5743,0)),D522) -> ORD26000043 | P522: =IF(L522>DATE(2026,9,30),"Oct-Due","Sep") -> Sep
A523: pay_420000048 | C523: ORD26000050 | D523: =UPPER(SUBSTITUTE(TRIM(C523),"-","")) -> ORD26000050 | E523: 46269 | F523: CAPTURE | G523: UPI | H523: 3499 | I523: 10.5 | J523: 1.89 | K523: 3486.61 | L523: 46271 | M523: STL-20260906 | N523: =IF(COUNTIF($A$2:A523,A523)>1,"DUP","OK") -> OK | O523: =IF(F523="REFUND",INDEX($D$2:$D$5743,MATCH(B523,$A$2:$A$5743,0)),D523) -> ORD26000050 | P523: =IF(L523>DATE(2026,9,30),"Oct-Due","Sep") -> Sep
A524: pay_420000091 | C524: ORD-26000097 | D524: =UPPER(SUBSTITUTE(TRIM(C524),"-","")) -> ORD26000097 | E524: 46269 | F524: CAPTURE | G524: Wallet | H524: 1098 | I524: 20.86 | J524: 3.75 | K524: 1073.39 | L524: 46271 | M524: STL-20260906 | N524: =IF(COUNTIF($A$2:A524,A524)>1,"DUP","OK") -> OK | O524: =IF(F524="REFUND",INDEX($D$2:$D$5743,MATCH(B524,$A$2:$A$5743,0)),D524) -> ORD26000097 | P524: =IF(L524>DATE(2026,9,30),"Oct-Due","Sep") -> Sep
A525: pay_420000104 | C525: ORD26000112 | D525: =UPPER(SUBSTITUTE(TRIM(C525),"-","")) -> ORD26000112 | E525: 46269 | F525: CAPTURE | G525: UPI | H525: 10297 | I525: 30.89 | J525: 5.56 | K525: 10260.55 | L525: 46271 | M525: STL-20260906 | N525: =IF(COUNTIF($A$2:A525,A525)>1,"DUP","OK") -> OK | O525: =IF(F525="REFUND",INDEX($D$2:$D$5743,MATCH(B525,$A$2:$A$5743,0)),D525) -> ORD26000112 | P525: =IF(L525>DATE(2026,9,30),"Oct-Due","Sep") -> Sep
A526: pay_420000108 | C526: ORD26000116 | D526: =UPPER(SUBSTITUTE(TRIM(C526),"-","")) -> ORD26000116 | E526: 46269 | F526: CAPTURE | G526: UPI | H526: 2499 | I526: 7.5 | J526: 1.35 | K526: 2490.15 | L526: 46271 | M526: STL-20260906 | N526: =IF(COUNTIF($A$2:A526,A526)>1,"DUP","OK") -> OK | O526: =IF(F526="REFUND",INDEX($D$2:$D$5743,MATCH(B526,$A$2:$A$5743,0)),D526) -> ORD26000116 | P526: =IF(L526>DATE(2026,9,30),"Oct-Due","Sep") -> Sep
A527: pay_420000110 | C527: ORD26000118 | D527: =UPPER(SUBSTITUTE(TRIM(C527),"-","")) -> ORD26000118 | E527: 46269 | F527: CAPTURE | G527: UPI | H527: 5998 | I527: 17.99 | J527: 3.24 | K527: 5976.77 | L527: 46271 | M527: STL-20260906 | N527: =IF(COUNTIF($A$2:A527,A527)>1,"DUP","OK") -> OK | O527: =IF(F527="REFUND",INDEX($D$2:$D$5743,MATCH(B527,$A$2:$A$5743,0)),D527) -> ORD26000118 | P527: =IF(L527>DATE(2026,9,30),"Oct-Due","Sep") -> Sep
A528: pay_420000150 | C528: ORD26000160 | D528: =UPPER(SUBSTITUTE(TRIM(C528),"-","")) -> ORD26000160 | E528: 46269 | F528: CAPTURE | G528: Card | H528: 1299 | I528: 23.38 | J528: 4.21 | K528: 1271.41 | L528: 46271 | M528: STL-20260906 | N528: =IF(COUNTIF($A$2:A528,A528)>1,"DUP","OK") -> OK | O528: =IF(F528="REFUND",INDEX($D$2:$D$5743,MATCH(B528,$A$2:$A$5743,0)),D528) -> ORD26000160 | P528: =IF(L528>DATE(2026,9,30),"Oct-Due","Sep") -> Sep
A529: pay_420000189 | C529: ORD26000202 | D529: =UPPER(SUBSTITUTE(TRIM(C529),"-","")) -> ORD26000202 | E529: 46269 | F529: CAPTURE | G529: UPI | H529: 3499 | I529: 10.5 | J529: 1.89 | K529: 3486.61 | L529: 46271 | M529: STL-20260906 | N529: =IF(COUNTIF($A$2:A529,A529)>1,"DUP","OK") -> OK | O529: =IF(F529="REFUND",INDEX($D$2:$D$5743,MATCH(B529,$A$2:$A$5743,0)),D529) -> ORD26000202 | P529: =IF(L529>DATE(2026,9,30),"Oct-Due","Sep") -> Sep
A530: pay_420000207 | C530: ORD26000221 | D530: =UPPER(SUBSTITUTE(TRIM(C530),"-","")) -> ORD26000221 | E530: 46269 | F530: CAPTURE | G530: UPI | H530: 1499 | I530: 0 | J530: 0 | K530: 1499 | L530: 46271 | M530: STL-20260906 | N530: =IF(COUNTIF($A$2:A530,A530)>1,"DUP","OK") -> OK | O530: =IF(F530="REFUND",INDEX($D$2:$D$5743,MATCH(B530,$A$2:$A$5743,0)),D530) -> ORD26000221 | P530: =IF(L530>DATE(2026,9,30),"Oct-Due","Sep") -> Sep
...

Sheet Rate Card
A1: payment_method | B1: amount_above | C1: amount_up_to | D1: mdr_pct | E1: gst_on_mdr_pct | F1: amount_up_to_clean | G1: mdr_rate | H1: gst_rate | I1: slab_label
A2: UPI | B2: 0 | C2: 2000 | D2: 0 | E2: 18 | F2: =IF(C2="",999999999,C2) -> 2000 | G2: =D2/100 -> 0 | H2: =E2/100 -> 0.18 | I2: =A2&" | above "&B2&" up to "&IF(C2="","no limit",C2) -> UPI | above 0 up to 2000
A3: UPI | B3: 2000 | D3: 0.3 | E3: 18 | F3: =IF(C3="",999999999,C3) -> 999999999 | G3: =D3/100 -> 0.003 | H3: =E3/100 -> 0.18 | I3: =A3&" | above "&B3&" up to "&IF(C3="","no limit",C3) -> UPI | above 2000 up to no limit
A4: Card | B4: 0 | C4: 2000 | D4: 1.8 | E4: 18 | F4: =IF(C4="",999999999,C4) -> 2000 | G4: =D4/100 -> 0.018 | H4: =E4/100 -> 0.18 | I4: =A4&" | above "&B4&" up to "&IF(C4="","no limit",C4) -> Card | above 0 up to 2000
A5: Card | B5: 2000 | D5: 1.6 | E5: 18 | F5: =IF(C5="",999999999,C5) -> 999999999 | G5: =D5/100 -> 0.016 | H5: =E5/100 -> 0.18 | I5: =A5&" | above "&B5&" up to "&IF(C5="","no limit",C5) -> Card | above 2000 up to no limit
A6: NetBanking | B6: 0 | C6: 2000 | D6: 1.5 | E6: 18 | F6: =IF(C6="",999999999,C6) -> 2000 | G6: =D6/100 -> 0.015 | H6: =E6/100 -> 0.18 | I6: =A6&" | above "&B6&" up to "&IF(C6="","no limit",C6) -> NetBanking | above 0 up to 2000
A7: NetBanking | B7: 2000 | C7: 10000 | D7: 1.2 | E7: 18 | F7: =IF(C7="",999999999,C7) -> 10000 | G7: =D7/100 -> 0.012 | H7: =E7/100 -> 0.18 | I7: =A7&" | above "&B7&" up to "&IF(C7="","no limit",C7) -> NetBanking | above 2000 up to 10000
A8: NetBanking | B8: 10000 | D8: 0.9 | E8: 18 | F8: =IF(C8="",999999999,C8) -> 999999999 | G8: =D8/100 -> 0.009 | H8: =E8/100 -> 0.18 | I8: =A8&" | above "&B8&" up to "&IF(C8="","no limit",C8) -> NetBanking | above 10000 up to no limit
A9: Wallet | B9: 0 | C9: 2000 | D9: 1.9 | E9: 18 | F9: =IF(C9="",999999999,C9) -> 2000 | G9: =D9/100 -> 0.019 | H9: =E9/100 -> 0.18 | I9: =A9&" | above "&B9&" up to "&IF(C9="","no limit",C9) -> Wallet | above 0 up to 2000
A10: Wallet | B10: 2000 | D10: 1.7 | E10: 18 | F10: =IF(C10="",999999999,C10) -> 999999999 | G10: =D10/100 -> 0.017 | H10: =E10/100 -> 0.18 | I10: =A10&" | above "&B10&" up to "&IF(C10="","no limit",C10) -> Wallet | above 2000 up to no limit

Sheet order_cleaned
A1: order_id | B1: order_date | C1: customer_id | D1: city | E1: payment_method | F1: order_amount | G1: order_status | H1: order_date_clean | I1: order_amount_clean | J1: city_clean | K1: capture_count | L1: capture_gross | M1: refund_count | N1: refund_amount | O1: exception_type | P1: exception_value
A2: ORD26000001 | B2: 21-09-2026 | C2: CUST28289 | D2: Pune | E2: UPI | F2: 299.0 | G2: Paid | H2: =IF(MID(B2,5,1)="-",DATE(LEFT(B2,4),MID(B2,6,2),RIGHT(B2,2)),DATE(RIGHT(B2,4),MID(B2,4,2),LEFT(B2,2))) -> 46286 | I2: =VALUE(SUBSTITUTE(F2,",","")) -> 299 | J2: =IF(TRIM(D2)="","Unknown",TRIM(D2)) -> Pune | K2: =COUNTIFS(pg_transaction_cleaned!$O$2:$O$5743,A2,pg_transaction_cleaned!$F$2:$F$5743,"CAPTURE") -> 1 | L2: =SUMIFS(pg_transaction_cleaned!$H$2:$H$5743,pg_transaction_cleaned!$O$2:$O$5743,A2,pg_transaction_cleaned!$F$2:$F$5743,"CAPTURE") -> 299 | M2: =COUNTIFS(pg_transaction_cleaned!$O$2:$O$5743,A2,pg_transaction_cleaned!$F$2:$F$5743,"REFUND") -> 0 | N2: =SUMIFS(pg_transaction_cleaned!$H$2:$H$5743,pg_transaction_cleaned!$O$2:$O$5743,A2,pg_transaction_cleaned!$F$2:$F$5743,"REFUND") -> 0 | O2: =IF(AND(G2="Paid",K2=0),"Paid, no payment",IF(AND(OR(G2="Failed",G2="Cancelled"),K2>0),"Payment on failed/cancelled",IF(K2>1,"Duplicate charge",IF(AND(K2=1,ROUND(L2-I2,2)<>0),"Amount difference",IF(AND(G2="Refunded",M2=0),"Refunded, no refund",IF(AND(G2<>"Refunded",M2>0),"Refund, order not Refunded",IF(AND(M2>0,ROUND(N2-I2,2)<>0),"Refund amount differs","OK"))))))) -> OK | P2: =IF(O2="OK",0,IF(O2="Paid, no payment",I2,IF(O2="Payment on failed/cancelled",L2,IF(OR(O2="Duplicate charge",O2="Amount difference"),L2-I2,IF(O2="Refunded, no refund",I2,N2))))) -> 0
A3: ORD26000002 | B3: 22/09/2026 | C3: CUST38657 | D3: Bengaluru | E3: UPI | F3: 4647.0 | G3: Paid | H3: =IF(MID(B3,5,1)="-",DATE(LEFT(B3,4),MID(B3,6,2),RIGHT(B3,2)),DATE(RIGHT(B3,4),MID(B3,4,2),LEFT(B3,2))) -> 46287 | I3: =VALUE(SUBSTITUTE(F3,",","")) -> 4647 | J3: =IF(TRIM(D3)="","Unknown",TRIM(D3)) -> Bengaluru | K3: =COUNTIFS(pg_transaction_cleaned!$O$2:$O$5743,A3,pg_transaction_cleaned!$F$2:$F$5743,"CAPTURE") -> 1 | L3: =SUMIFS(pg_transaction_cleaned!$H$2:$H$5743,pg_transaction_cleaned!$O$2:$O$5743,A3,pg_transaction_cleaned!$F$2:$F$5743,"CAPTURE") -> 4647 | M3: =COUNTIFS(pg_transaction_cleaned!$O$2:$O$5743,A3,pg_transaction_cleaned!$F$2:$F$5743,"REFUND") -> 0 | N3: =SUMIFS(pg_transaction_cleaned!$H$2:$H$5743,pg_transaction_cleaned!$O$2:$O$5743,A3,pg_transaction_cleaned!$F$2:$F$5743,"REFUND") -> 0 | O3: =IF(AND(G3="Paid",K3=0),"Paid, no payment",IF(AND(OR(G3="Failed",G3="Cancelled"),K3>0),"Payment on failed/cancelled",IF(K3>1,"Duplicate charge",IF(AND(K3=1,ROUND(L3-I3,2)<>0),"Amount difference",IF(AND(G3="Refunded",M3=0),"Refunded, no refund",IF(AND(G3<>"Refunded",M3>0),"Refund, order not Refunded",IF(AND(M3>0,ROUND(N3-I3,2)<>0),"Refund amount differs","OK"))))))) -> OK | P3: =IF(O3="OK",0,IF(O3="Paid, no payment",I3,IF(O3="Payment on failed/cancelled",L3,IF(OR(O3="Duplicate charge",O3="Amount difference"),L3-I3,IF(O3="Refunded, no refund",I3,N3))))) -> 0
A4: ORD26000003 | B4: 17-09-2026 | C4: CUST81426 | D4: Kolkata | E4: Card | F4: 2098.0 | G4: Paid | H4: =IF(MID(B4,5,1)="-",DATE(LEFT(B4,4),MID(B4,6,2),RIGHT(B4,2)),DATE(RIGHT(B4,4),MID(B4,4,2),LEFT(B4,2))) -> 46282 | I4: =VALUE(SUBSTITUTE(F4,",","")) -> 2098 | J4: =IF(TRIM(D4)="","Unknown",TRIM(D4)) -> Kolkata | K4: =COUNTIFS(pg_transaction_cleaned!$O$2:$O$5743,A4,pg_transaction_cleaned!$F$2:$F$5743,"CAPTURE") -> 1 | L4: =SUMIFS(pg_transaction_cleaned!$H$2:$H$5743,pg_transaction_cleaned!$O$2:$O$5743,A4,pg_transaction_cleaned!$F$2:$F$5743,"CAPTURE") -> 2098 | M4: =COUNTIFS(pg_transaction_cleaned!$O$2:$O$5743,A4,pg_transaction_cleaned!$F$2:$F$5743,"REFUND") -> 0 | N4: =SUMIFS(pg_transaction_cleaned!$H$2:$H$5743,pg_transaction_cleaned!$O$2:$O$5743,A4,pg_transaction_cleaned!$F$2:$F$5743,"REFUND") -> 0 | O4: =IF(AND(G4="Paid",K4=0),"Paid, no payment",IF(AND(OR(G4="Failed",G4="Cancelled"),K4>0),"Payment on failed/cancelled",IF(K4>1,"Duplicate charge",IF(AND(K4=1,ROUND(L4-I4,2)<>0),"Amount difference",IF(AND(G4="Refunded",M4=0),"Refunded, no refund",IF(AND(G4<>"Refunded",M4>0),"Refund, order not Refunded",IF(AND(M4>0,ROUND(N4-I4,2)<>0),"Refund amount differs","OK"))))))) -> OK | P4: =IF(O4="OK",0,IF(O4="Paid, no payment",I4,IF(O4="Payment on failed/cancelled",L4,IF(OR(O4="Duplicate charge",O4="Amount difference"),L4-I4,IF(O4="Refunded, no refund",I4,N4))))) -> 0
A5: ORD26000004 | B5: 2026-09-08 | C5: CUST30926 | D5: Kolkata | E5: UPI | F5: 3298.0 | G5: Paid | H5: =IF(MID(B5,5,1)="-",DATE(LEFT(B5,4),MID(B5,6,2),RIGHT(B5,2)),DATE(RIGHT(B5,4),MID(B5,4,2),LEFT(B5,2))) -> 46273 | I5: =VALUE(SUBSTITUTE(F5,",","")) -> 3298 | J5: =IF(TRIM(D5)="","Unknown",TRIM(D5)) -> Kolkata | K5: =COUNTIFS(pg_transaction_cleaned!$O$2:$O$5743,A5,pg_transaction_cleaned!$F$2:$F$5743,"CAPTURE") -> 1 | L5: =SUMIFS(pg_transaction_cleaned!$H$2:$H$5743,pg_transaction_cleaned!$O$2:$O$5743,A5,pg_transaction_cleaned!$F$2:$F$5743,"CAPTURE") -> 3298 | M5: =COUNTIFS(pg_transaction_cleaned!$O$2:$O$5743,A5,pg_transaction_cleaned!$F$2:$F$5743,"REFUND") -> 0 | N5: =SUMIFS(pg_transaction_cleaned!$H$2:$H$5743,pg_transaction_cleaned!$O$2:$O$5743,A5,pg_transaction_cleaned!$F$2:$F$5743,"REFUND") -> 0 | O5: =IF(AND(G5="Paid",K5=0),"Paid, no payment",IF(AND(OR(G5="Failed",G5="Cancelled"),K5>0),"Payment on failed/cancelled",IF(K5>1,"Duplicate charge",IF(AND(K5=1,ROUND(L5-I5,2)<>0),"Amount difference",IF(AND(G5="Refunded",M5=0),"Refunded, no refund",IF(AND(G5<>"Refunded",M5>0),"Refund, order not Refunded",IF(AND(M5>0,ROUND(N5-I5,2)<>0),"Refund amount differs","OK"))))))) -> OK | P5: =IF(O5="OK",0,IF(O5="Paid, no payment",I5,IF(O5="Payment on failed/cancelled",L5,IF(OR(O5="Duplicate charge",O5="Amount difference"),L5-I5,IF(O5="Refunded, no refund",I5,N5))))) -> 0
A6: ORD26000005 | B6: 2026-09-11 | C6: CUST23396 | D6: Pune | E6: Card | F6: 499.0 | G6: Paid | H6: =IF(MID(B6,5,1)="-",DATE(LEFT(B6,4),MID(B6,6,2),RIGHT(B6,2)),DATE(RIGHT(B6,4),MID(B6,4,2),LEFT(B6,2))) -> 46276 | I6: =VALUE(SUBSTITUTE(F6,",","")) -> 499 | J6: =IF(TRIM(D6)="","Unknown",TRIM(D6)) -> Pune | K6: =COUNTIFS(pg_transaction_cleaned!$O$2:$O$5743,A6,pg_transaction_cleaned!$F$2:$F$5743,"CAPTURE") -> 1 | L6: =SUMIFS(pg_transaction_cleaned!$H$2:$H$5743,pg_transaction_cleaned!$O$2:$O$5743,A6,pg_transaction_cleaned!$F$2:$F$5743,"CAPTURE") -> 499 | M6: =COUNTIFS(pg_transaction_cleaned!$O$2:$O$5743,A6,pg_transaction_cleaned!$F$2:$F$5743,"REFUND") -> 0 | N6: =SUMIFS(pg_transaction_cleaned!$H$2:$H$5743,pg_transaction_cleaned!$O$2:$O$5743,A6,pg_transaction_cleaned!$F$2:$F$5743,"REFUND") -> 0 | O6: =IF(AND(G6="Paid",K6=0),"Paid, no payment",IF(AND(OR(G6="Failed",G6="Cancelled"),K6>0),"Payment on failed/cancelled",IF(K6>1,"Duplicate charge",IF(AND(K6=1,ROUND(L6-I6,2)<>0),"Amount difference",IF(AND(G6="Refunded",M6=0),"Refunded, no refund",IF(AND(G6<>"Refunded",M6>0),"Refund, order not Refunded",IF(AND(M6>0,ROUND(N6-I6,2)<>0),"Refund amount differs","OK"))))))) -> OK | P6: =IF(O6="OK",0,IF(O6="Paid, no payment",I6,IF(O6="Payment on failed/cancelled",L6,IF(OR(O6="Duplicate charge",O6="Amount difference"),L6-I6,IF(O6="Refunded, no refund",I6,N6))))) -> 0
A7: ORD26000006 | B7: 2026-09-13 | C7: CUST15695 | D7: Ahmedabad | E7: Card | F7: 999.0 | G7: Paid | H7: =IF(MID(B7,5,1)="-",DATE(LEFT(B7,4),MID(B7,6,2),RIGHT(B7,2)),DATE(RIGHT(B7,4),MID(B7,4,2),LEFT(B7,2))) -> 46278 | I7: =VALUE(SUBSTITUTE(F7,",","")) -> 999 | J7: =IF(TRIM(D7)="","Unknown",TRIM(D7)) -> Ahmedabad | K7: =COUNTIFS(pg_transaction_cleaned!$O$2:$O$5743,A7,pg_transaction_cleaned!$F$2:$F$5743,"CAPTURE") -> 1 | L7: =SUMIFS(pg_transaction_cleaned!$H$2:$H$5743,pg_transaction_cleaned!$O$2:$O$5743,A7,pg_transaction_cleaned!$F$2:$F$5743,"CAPTURE") -> 999 | M7: =COUNTIFS(pg_transaction_cleaned!$O$2:$O$5743,A7,pg_transaction_cleaned!$F$2:$F$5743,"REFUND") -> 0 | N7: =SUMIFS(pg_transaction_cleaned!$H$2:$H$5743,pg_transaction_cleaned!$O$2:$O$5743,A7,pg_transaction_cleaned!$F$2:$F$5743,"REFUND") -> 0 | O7: =IF(AND(G7="Paid",K7=0),"Paid, no payment",IF(AND(OR(G7="Failed",G7="Cancelled"),K7>0),"Payment on failed/cancelled",IF(K7>1,"Duplicate charge",IF(AND(K7=1,ROUND(L7-I7,2)<>0),"Amount difference",IF(AND(G7="Refunded",M7=0),"Refunded, no refund",IF(AND(G7<>"Refunded",M7>0),"Refund, order not Refunded",IF(AND(M7>0,ROUND(N7-I7,2)<>0),"Refund amount differs","OK"))))))) -> OK | P7: =IF(O7="OK",0,IF(O7="Paid, no payment",I7,IF(O7="Payment on failed/cancelled",L7,IF(OR(O7="Duplicate charge",O7="Amount difference"),L7-I7,IF(O7="Refunded, no refund",I7,N7))))) -> 0
A8: ORD26000007 | B8: 18-09-2026 | C8: CUST92397 | D8: Lucknow | E8: UPI | F8: 1299.0 | G8: Paid | H8: =IF(MID(B8,5,1)="-",DATE(LEFT(B8,4),MID(B8,6,2),RIGHT(B8,2)),DATE(RIGHT(B8,4),MID(B8,4,2),LEFT(B8,2))) -> 46283 | I8: =VALUE(SUBSTITUTE(F8,",","")) -> 1299 | J8: =IF(TRIM(D8)="","Unknown",TRIM(D8)) -> Lucknow | K8: =COUNTIFS(pg_transaction_cleaned!$O$2:$O$5743,A8,pg_transaction_cleaned!$F$2:$F$5743,"CAPTURE") -> 1 | L8: =SUMIFS(pg_transaction_cleaned!$H$2:$H$5743,pg_transaction_cleaned!$O$2:$O$5743,A8,pg_transaction_cleaned!$F$2:$F$5743,"CAPTURE") -> 1299 | M8: =COUNTIFS(pg_transaction_cleaned!$O$2:$O$5743,A8,pg_transaction_cleaned!$F$2:$F$5743,"REFUND") -> 0 | N8: =SUMIFS(pg_transaction_cleaned!$H$2:$H$5743,pg_transaction_cleaned!$O$2:$O$5743,A8,pg_transaction_cleaned!$F$2:$F$5743,"REFUND") -> 0 | O8: =IF(AND(G8="Paid",K8=0),"Paid, no payment",IF(AND(OR(G8="Failed",G8="Cancelled"),K8>0),"Payment on failed/cancelled",IF(K8>1,"Duplicate charge",IF(AND(K8=1,ROUND(L8-I8,2)<>0),"Amount difference",IF(AND(G8="Refunded",M8=0),"Refunded, no refund",IF(AND(G8<>"Refunded",M8>0),"Refund, order not Refunded",IF(AND(M8>0,ROUND(N8-I8,2)<>0),"Refund amount differs","OK"))))))) -> OK | P8: =IF(O8="OK",0,IF(O8="Paid, no payment",I8,IF(O8="Payment on failed/cancelled",L8,IF(OR(O8="Duplicate charge",O8="Amount difference"),L8-I8,IF(O8="Refunded, no refund",I8,N8))))) -> 0
A9: ORD26000008 | B9: 2026-09-29 | C9: CUST96673 | D9: Bengaluru | E9: UPI | F9: 2499.0 | G9: Paid | H9: =IF(MID(B9,5,1)="-",DATE(LEFT(B9,4),MID(B9,6,2),RIGHT(B9,2)),DATE(RIGHT(B9,4),MID(B9,4,2),LEFT(B9,2))) -> 46294 | I9: =VALUE(SUBSTITUTE(F9,",","")) -> 2499 | J9: =IF(TRIM(D9)="","Unknown",TRIM(D9)) -> Bengaluru | K9: =COUNTIFS(pg_transaction_cleaned!$O$2:$O$5743,A9,pg_transaction_cleaned!$F$2:$F$5743,"CAPTURE") -> 1 | L9: =SUMIFS(pg_transaction_cleaned!$H$2:$H$5743,pg_transaction_cleaned!$O$2:$O$5743,A9,pg_transaction_cleaned!$F$2:$F$5743,"CAPTURE") -> 2499 | M9: =COUNTIFS(pg_transaction_cleaned!$O$2:$O$5743,A9,pg_transaction_cleaned!$F$2:$F$5743,"REFUND") -> 0 | N9: =SUMIFS(pg_transaction_cleaned!$H$2:$H$5743,pg_transaction_cleaned!$O$2:$O$5743,A9,pg_transaction_cleaned!$F$2:$F$5743,"REFUND") -> 0 | O9: =IF(AND(G9="Paid",K9=0),"Paid, no payment",IF(AND(OR(G9="Failed",G9="Cancelled"),K9>0),"Payment on failed/cancelled",IF(K9>1,"Duplicate charge",IF(AND(K9=1,ROUND(L9-I9,2)<>0),"Amount difference",IF(AND(G9="Refunded",M9=0),"Refunded, no refund",IF(AND(G9<>"Refunded",M9>0),"Refund, order not Refunded",IF(AND(M9>0,ROUND(N9-I9,2)<>0),"Refund amount differs","OK"))))))) -> OK | P9: =IF(O9="OK",0,IF(O9="Paid, no payment",I9,IF(O9="Payment on failed/cancelled",L9,IF(OR(O9="Duplicate charge",O9="Amount difference"),L9-I9,IF(O9="Refunded, no refund",I9,N9))))) -> 0
A10: ORD26000009 | B10: 25-09-2026 | C10: CUST59823 | D10: Hyderabad | E10: NetBanking | F10: 349.0 | G10: Paid | H10: =IF(MID(B10,5,1)="-",DATE(LEFT(B10,4),MID(B10,6,2),RIGHT(B10,2)),DATE(RIGHT(B10,4),MID(B10,4,2),LEFT(B10,2))) -> 46290 | I10: =VALUE(SUBSTITUTE(F10,",","")) -> 349 | J10: =IF(TRIM(D10)="","Unknown",TRIM(D10)) -> Hyderabad | K10: =COUNTIFS(pg_transaction_cleaned!$O$2:$O$5743,A10,pg_transaction_cleaned!$F$2:$F$5743,"CAPTURE") -> 1 | L10: =SUMIFS(pg_transaction_cleaned!$H$2:$H$5743,pg_transaction_cleaned!$O$2:$O$5743,A10,pg_transaction_cleaned!$F$2:$F$5743,"CAPTURE") -> 349 | M10: =COUNTIFS(pg_transaction_cleaned!$O$2:$O$5743,A10,pg_transaction_cleaned!$F$2:$F$5743,"REFUND") -> 0 | N10: =SUMIFS(pg_transaction_cleaned!$H$2:$H$5743,pg_transaction_cleaned!$O$2:$O$5743,A10,pg_transaction_cleaned!$F$2:$F$5743,"REFUND") -> 0 | O10: =IF(AND(G10="Paid",K10=0),"Paid, no payment",IF(AND(OR(G10="Failed",G10="Cancelled"),K10>0),"Payment on failed/cancelled",IF(K10>1,"Duplicate charge",IF(AND(K10=1,ROUND(L10-I10,2)<>0),"Amount difference",IF(AND(G10="Refunded",M10=0),"Refunded, no refund",IF(AND(G10<>"Refunded",M10>0),"Refund, order not Refunded",IF(AND(M10>0,ROUND(N10-I10,2)<>0),"Refund amount differs","OK"))))))) -> OK | P10: =IF(O10="OK",0,IF(O10="Paid, no payment",I10,IF(O10="Payment on failed/cancelled",L10,IF(OR(O10="Duplicate charge",O10="Amount difference"),L10-I10,IF(O10="Refunded, no refund",I10,N10))))) -> 0
A11: ORD26000010 | B11: 15-09-2026 | C11: CUST44993 | D11: Pune | E11: UPI | F11: 9497.0 | G11: Paid | H11: =IF(MID(B11,5,1)="-",DATE(LEFT(B11,4),MID(B11,6,2),RIGHT(B11,2)),DATE(RIGHT(B11,4),MID(B11,4,2),LEFT(B11,2))) -> 46280 | I11: =VALUE(SUBSTITUTE(F11,",","")) -> 9497 | J11: =IF(TRIM(D11)="","Unknown",TRIM(D11)) -> Pune | K11: =COUNTIFS(pg_transaction_cleaned!$O$2:$O$5743,A11,pg_transaction_cleaned!$F$2:$F$5743,"CAPTURE") -> 1 | L11: =SUMIFS(pg_transaction_cleaned!$H$2:$H$5743,pg_transaction_cleaned!$O$2:$O$5743,A11,pg_transaction_cleaned!$F$2:$F$5743,"CAPTURE") -> 9497 | M11: =COUNTIFS(pg_transaction_cleaned!$O$2:$O$5743,A11,pg_transaction_cleaned!$F$2:$F$5743,"REFUND") -> 0 | N11: =SUMIFS(pg_transaction_cleaned!$H$2:$H$5743,pg_transaction_cleaned!$O$2:$O$5743,A11,pg_transaction_cleaned!$F$2:$F$5743,"REFUND") -> 0 | O11: =IF(AND(G11="Paid",K11=0),"Paid, no payment",IF(AND(OR(G11="Failed",G11="Cancelled"),K11>0),"Payment on failed/cancelled",IF(K11>1,"Duplicate charge",IF(AND(K11=1,ROUND(L11-I11,2)<>0),"Amount difference",IF(AND(G11="Refunded",M11=0),"Refunded, no refund",IF(AND(G11<>"Refunded",M11>0),"Refund, order not Refunded",IF(AND(M11>0,ROUND(N11-I11,2)<>0),"Refund amount differs","OK"))))))) -> OK | P11: =IF(O11="OK",0,IF(O11="Paid, no payment",I11,IF(O11="Payment on failed/cancelled",L11,IF(OR(O11="Duplicate charge",O11="Amount difference"),L11-I11,IF(O11="Refunded, no refund",I11,N11))))) -> 0
A12: ORD26000011 | B12: 20-09-2026 | C12: CUST45382 | D12: Jaipur | E12: UPI | F12: 5797.0 | G12: Paid | H12: =IF(MID(B12,5,1)="-",DATE(LEFT(B12,4),MID(B12,6,2),RIGHT(B12,2)),DATE(RIGHT(B12,4),MID(B12,4,2),LEFT(B12,2))) -> 46285 | I12: =VALUE(SUBSTITUTE(F12,",","")) -> 5797 | J12: =IF(TRIM(D12)="","Unknown",TRIM(D12)) -> Jaipur | K12: =COUNTIFS(pg_transaction_cleaned!$O$2:$O$5743,A12,pg_transaction_cleaned!$F$2:$F$5743,"CAPTURE") -> 1 | L12: =SUMIFS(pg_transaction_cleaned!$H$2:$H$5743,pg_transaction_cleaned!$O$2:$O$5743,A12,pg_transaction_cleaned!$F$2:$F$5743,"CAPTURE") -> 5797 | M12: =COUNTIFS(pg_transaction_cleaned!$O$2:$O$5743,A12,pg_transaction_cleaned!$F$2:$F$5743,"REFUND") -> 0 | N12: =SUMIFS(pg_transaction_cleaned!$H$2:$H$5743,pg_transaction_cleaned!$O$2:$O$5743,A12,pg_transaction_cleaned!$F$2:$F$5743,"REFUND") -> 0 | O12: =IF(AND(G12="Paid",K12=0),"Paid, no payment",IF(AND(OR(G12="Failed",G12="Cancelled"),K12>0),"Payment on failed/cancelled",IF(K12>1,"Duplicate charge",IF(AND(K12=1,ROUND(L12-I12,2)<>0),"Amount difference",IF(AND(G12="Refunded",M12=0),"Refunded, no refund",IF(AND(G12<>"Refunded",M12>0),"Refund, order not Refunded",IF(AND(M12>0,ROUND(N12-I12,2)<>0),"Refund amount differs","OK"))))))) -> OK | P12: =IF(O12="OK",0,IF(O12="Paid, no payment",I12,IF(O12="Payment on failed/cancelled",L12,IF(OR(O12="Duplicate charge",O12="Amount difference"),L12-I12,IF(O12="Refunded, no refund",I12,N12))))) -> 0
A13: ORD26000012 | B13: 2026-09-08 | C13: CUST14207 | D13: Chennai | E13: UPI | F13: 13997.0 | G13: Paid | H13: =IF(MID(B13,5,1)="-",DATE(LEFT(B13,4),MID(B13,6,2),RIGHT(B13,2)),DATE(RIGHT(B13,4),MID(B13,4,2),LEFT(B13,2))) -> 46273 | I13: =VALUE(SUBSTITUTE(F13,",","")) -> 13997 | J13: =IF(TRIM(D13)="","Unknown",TRIM(D13)) -> Chennai | K13: =COUNTIFS(pg_transaction_cleaned!$O$2:$O$5743,A13,pg_transaction_cleaned!$F$2:$F$5743,"CAPTURE") -> 1 | L13: =SUMIFS(pg_transaction_cleaned!$H$2:$H$5743,pg_transaction_cleaned!$O$2:$O$5743,A13,pg_transaction_cleaned!$F$2:$F$5743,"CAPTURE") -> 13997 | M13: =COUNTIFS(pg_transaction_cleaned!$O$2:$O$5743,A13,pg_transaction_cleaned!$F$2:$F$5743,"REFUND") -> 0 | N13: =SUMIFS(pg_transaction_cleaned!$H$2:$H$5743,pg_transaction_cleaned!$O$2:$O$5743,A13,pg_transaction_cleaned!$F$2:$F$5743,"REFUND") -> 0 | O13: =IF(AND(G13="Paid",K13=0),"Paid, no payment",IF(AND(OR(G13="Failed",G13="Cancelled"),K13>0),"Payment on failed/cancelled",IF(K13>1,"Duplicate charge",IF(AND(K13=1,ROUND(L13-I13,2)<>0),"Amount difference",IF(AND(G13="Refunded",M13=0),"Refunded, no refund",IF(AND(G13<>"Refunded",M13>0),"Refund, order not Refunded",IF(AND(M13>0,ROUND(N13-I13,2)<>0),"Refund amount differs","OK"))))))) -> OK | P13: =IF(O13="OK",0,IF(O13="Paid, no payment",I13,IF(O13="Payment on failed/cancelled",L13,IF(OR(O13="Duplicate charge",O13="Amount difference"),L13-I13,IF(O13="Refunded, no refund",I13,N13))))) -> 0
... A80: ORD26000079 | B80: 2026-09-20 | C80: CUST76162 | D80: Kolkata | E80: Card | F80: 4999.0 | G80: Failed | H80: =IF(MID(B80,5,1)="-",DATE(LEFT(B80,4),MID(B80,6,2),RIGHT(B80,2)),DATE(RIGHT(B80,4),MID(B80,4,2),LEFT(B80,2))) -> 46285 | I80: =VALUE(SUBSTITUTE(F80,",","")) -> 4999 | J80: =IF(TRIM(D80)="","Unknown",TRIM(D80)) -> Kolkata | K80: =COUNTIFS(pg_transaction_cleaned!$O$2:$O$5743,A80,pg_transaction_cleaned!$F$2:$F$5743,"CAPTURE") -> 0 | L80: =SUMIFS(pg_transaction_cleaned!$H$2:$H$5743,pg_transaction_cleaned!$O$2:$O$5743,A80,pg_transaction_cleaned!$F$2:$F$5743,"CAPTURE") -> 0 | M80: =COUNTIFS(pg_transaction_cleaned!$O$2:$O$5743,A80,pg_transaction_cleaned!$F$2:$F$5743,"REFUND") -> 0 | N80: =SUMIFS(pg_transaction_cleaned!$H$2:$H$5743,pg_transaction_cleaned!$O$2:$O$5743,A80,pg_transaction_cleaned!$F$2:$F$5743,"REFUND") -> 0 | O80: =IF(AND(G80="Paid",K80=0),"Paid, no payment",IF(AND(OR(G80="Failed",G80="Cancelled"),K80>0),"Payment on failed/cancelled",IF(K80>1,"Duplicate charge",IF(AND(K80=1,ROUND(L80-I80,2)<>0),"Amount difference",IF(AND(G80="Refunded",M80=0),"Refunded, no refund",IF(AND(G80<>"Refunded",M80>0),"Refund, order not Refunded",IF(AND(M80>0,ROUND(N80-I80,2)<>0),"Refund amount differs","OK"))))))) -> OK | P80: =IF(O80="OK",0,IF(O80="Paid, no payment",I80,IF(O80="Payment on failed/cancelled",L80,IF(OR(O80="Duplicate charge",O80="Amount difference"),L80-I80,IF(O80="Refunded, no refund",I80,N80))))) -> 0
A81: ORD26000080 | B81: 27-09-2026 | C81: CUST43972 | E81: UPI | F81: 1998.0 | G81: Paid | H81: =IF(MID(B81,5,1)="-",DATE(LEFT(B81,4),MID(B81,6,2),RIGHT(B81,2)),DATE(RIGHT(B81,4),MID(B81,4,2),LEFT(B81,2))) -> 46292 | I81: =VALUE(SUBSTITUTE(F81,",","")) -> 1998 | J81: =IF(TRIM(D81)="","Unknown",TRIM(D81)) -> Unknown | K81: =COUNTIFS(pg_transaction_cleaned!$O$2:$O$5743,A81,pg_transaction_cleaned!$F$2:$F$5743,"CAPTURE") -> 1 | L81: =SUMIFS(pg_transaction_cleaned!$H$2:$H$5743,pg_transaction_cleaned!$O$2:$O$5743,A81,pg_transaction_cleaned!$F$2:$F$5743,"CAPTURE") -> 1998 | M81: =COUNTIFS(pg_transaction_cleaned!$O$2:$O$5743,A81,pg_transaction_cleaned!$F$2:$F$5743,"REFUND") -> 0 | N81: =SUMIFS(pg_transaction_cleaned!$H$2:$H$5743,pg_transaction_cleaned!$O$2:$O$5743,A81,pg_transaction_cleaned!$F$2:$F$5743,"REFUND") -> 0 | O81: =IF(AND(G81="Paid",K81=0),"Paid, no payment",IF(AND(OR(G81="Failed",G81="Cancelled"),K81>0),"Payment on failed/cancelled",IF(K81>1,"Duplicate charge",IF(AND(K81=1,ROUND(L81-I81,2)<>0),"Amount difference",IF(AND(G81="Refunded",M81=0),"Refunded, no refund",IF(AND(G81<>"Refunded",M81>0),"Refund, order not Refunded",IF(AND(M81>0,ROUND(N81-I81,2)<>0),"Refund amount differs","OK"))))))) -> OK | P81: =IF(O81="OK",0,IF(O81="Paid, no payment",I81,IF(O81="Payment on failed/cancelled",L81,IF(OR(O81="Duplicate charge",O81="Amount difference"),L81-I81,IF(O81="Refunded, no refund",I81,N81))))) -> 0
A82: ORD26000081 | B82: 2026-09-27 | C82: CUST45992 | D82: Ahmedabad | E82: Card | F82: 10797.0 | G82: Paid | H82: =IF(MID(B82,5,1)="-",DATE(LEFT(B82,4),MID(B82,6,2),RIGHT(B82,2)),DATE(RIGHT(B82,4),MID(B82,4,2),LEFT(B82,2))) -> 46292 | I82: =VALUE(SUBSTITUTE(F82,",","")) -> 10797 | J82: =IF(TRIM(D82)="","Unknown",TRIM(D82)) -> Ahmedabad | K82: =COUNTIFS(pg_transaction_cleaned!$O$2:$O$5743,A82,pg_transaction_cleaned!$F$2:$F$5743,"CAPTURE") -> 1 | L82: =SUMIFS(pg_transaction_cleaned!$H$2:$H$5743,pg_transaction_cleaned!$O$2:$O$5743,A82,pg_transaction_cleaned!$F$2:$F$5743,"CAPTURE") -> 10797 | M82: =COUNTIFS(pg_transaction_cleaned!$O$2:$O$5743,A82,pg_transaction_cleaned!$F$2:$F$5743,"REFUND") -> 0 | N82: =SUMIFS(pg_transaction_cleaned!$H$2:$H$5743,pg_transaction_cleaned!$O$2:$O$5743,A82,pg_transaction_cleaned!$F$2:$F$5743,"REFUND") -> 0 | O82: =IF(AND(G82="Paid",K82=0),"Paid, no payment",IF(AND(OR(G82="Failed",G82="Cancelled"),K82>0),"Payment on failed/cancelled",IF(K82>1,"Duplicate charge",IF(AND(K82=1,ROUND(L82-I82,2)<>0),"Amount difference",IF(AND(G82="Refunded",M82=0),"Refunded, no refund",IF(AND(G82<>"Refunded",M82>0),"Refund, order not Refunded",IF(AND(M82>0,ROUND(N82-I82,2)<>0),"Refund amount differs","OK"))))))) -> OK | P82: =IF(O82="OK",0,IF(O82="Paid, no payment",I82,IF(O82="Payment on failed/cancelled",L82,IF(OR(O82="Duplicate charge",O82="Amount difference"),L82-I82,IF(O82="Refunded, no refund",I82,N82))))) -> 0
A83: ORD26000082 | B83: 03-09-2026 | C83: CUST20561 | D83: Delhi | E83: Wallet | F83: 2197.0 | G83: Paid | H83: =IF(MID(B83,5,1)="-",DATE(LEFT(B83,4),MID(B83,6,2),RIGHT(B83,2)),DATE(RIGHT(B83,4),MID(B83,4,2),LEFT(B83,2))) -> 46268 | I83: =VALUE(SUBSTITUTE(F83,",","")) -> 2197 | J83: =IF(TRIM(D83)="","Unknown",TRIM(D83)) -> Delhi | K83: =COUNTIFS(pg_transaction_cleaned!$O$2:$O$5743,A83,pg_transaction_cleaned!$F$2:$F$5743,"CAPTURE") -> 1 | L83: =SUMIFS(pg_transaction_cleaned!$H$2:$H$5743,pg_transaction_cleaned!$O$2:$O$5743,A83,pg_transaction_cleaned!$F$2:$F$5743,"CAPTURE") -> 2197 | M83: =COUNTIFS(pg_transaction_cleaned!$O$2:$O$5743,A83,pg_transaction_cleaned!$F$2:$F$5743,"REFUND") -> 0 | N83: =SUMIFS(pg_transaction_cleaned!$H$2:$H$5743,pg_transaction_cleaned!$O$2:$O$5743,A83,pg_transaction_cleaned!$F$2:$F$5743,"REFUND") -> 0 | O83: =IF(AND(G83="Paid",K83=0),"Paid, no payment",IF(AND(OR(G83="Failed",G83="Cancelled"),K83>0),"Payment on failed/cancelled",IF(K83>1,"Duplicate charge",IF(AND(K83=1,ROUND(L83-I83,2)<>0),"Amount difference",IF(AND(G83="Refunded",M83=0),"Refunded, no refund",IF(AND(G83<>"Refunded",M83>0),"Refund, order not Refunded",IF(AND(M83>0,ROUND(N83-I83,2)<>0),"Refund amount differs","OK"))))))) -> OK | P83: =IF(O83="OK",0,IF(O83="Paid, no payment",I83,IF(O83="Payment on failed/cancelled",L83,IF(OR(O83="Duplicate charge",O83="Amount difference"),L83-I83,IF(O83="Refunded, no refund",I83,N83))))) -> 0
A84: ORD26000083 | B84: 05-09-2026 | C84: CUST18418 | D84: Kolkata | E84: Card | F84: 1299.0 | G84: Paid | H84: =IF(MID(B84,5,1)="-",DATE(LEFT(B84,4),MID(B84,6,2),RIGHT(B84,2)),DATE(RIGHT(B84,4),MID(B84,4,2),LEFT(B84,2))) -> 46270 | I84: =VALUE(SUBSTITUTE(F84,",","")) -> 1299 | J84: =IF(TRIM(D84)="","Unknown",TRIM(D84)) -> Kolkata | K84: =COUNTIFS(pg_transaction_cleaned!$O$2:$O$5743,A84,pg_transaction_cleaned!$F$2:$F$5743,"CAPTURE") -> 1 | L84: =SUMIFS(pg_transaction_cleaned!$H$2:$H$5743,pg_transaction_cleaned!$O$2:$O$5743,A84,pg_transaction_cleaned!$F$2:$F$5743,"CAPTURE") -> 1299 | M84: =COUNTIFS(pg_transaction_cleaned!$O$2:$O$5743,A84,pg_transaction_cleaned!$F$2:$F$5743,"REFUND") -> 0 | N84: =SUMIFS(pg_transaction_cleaned!$H$2:$H$5743,pg_transaction_cleaned!$O$2:$O$5743,A84,pg_transaction_cleaned!$F$2:$F$5743,"REFUND") -> 0 | O84: =IF(AND(G84="Paid",K84=0),"Paid, no payment",IF(AND(OR(G84="Failed",G84="Cancelled"),K84>0),"Payment on failed/cancelled",IF(K84>1,"Duplicate charge",IF(AND(K84=1,ROUND(L84-I84,2)<>0),"Amount difference",IF(AND(G84="Refunded",M84=0),"Refunded, no refund",IF(AND(G84<>"Refunded",M84>0),"Refund, order not Refunded",IF(AND(M84>0,ROUND(N84-I84,2)<>0),"Refund amount differs","OK"))))))) -> OK | P84: =IF(O84="OK",0,IF(O84="Paid, no payment",I84,IF(O84="Payment on failed/cancelled",L84,IF(OR(O84="Duplicate charge",O84="Amount difference"),L84-I84,IF(O84="Refunded, no refund",I84,N84))))) -> 0
A85: ORD26000084 | B85: 14/09/2026 | C85: CUST65069 | D85: Kolkata | E85: UPI | F85: 1799.0 | G85: Paid | H85: =IF(MID(B85,5,1)="-",DATE(LEFT(B85,4),MID(B85,6,2),RIGHT(B85,2)),DATE(RIGHT(B85,4),MID(B85,4,2),LEFT(B85,2))) -> 46279 | I85: =VALUE(SUBSTITUTE(F85,",","")) -> 1799 | J85: =IF(TRIM(D85)="","Unknown",TRIM(D85)) -> Kolkata | K85: =COUNTIFS(pg_transaction_cleaned!$O$2:$O$5743,A85,pg_transaction_cleaned!$F$2:$F$5743,"CAPTURE") -> 1 | L85: =SUMIFS(pg_transaction_cleaned!$H$2:$H$5743,pg_transaction_cleaned!$O$2:$O$5743,A85,pg_transaction_cleaned!$F$2:$F$5743,"CAPTURE") -> 1799 | M85: =COUNTIFS(pg_transaction_cleaned!$O$2:$O$5743,A85,pg_transaction_cleaned!$F$2:$F$5743,"REFUND") -> 0 | N85: =SUMIFS(pg_transaction_cleaned!$H$2:$H$5743,pg_transaction_cleaned!$O$2:$O$5743,A85,pg_transaction_cleaned!$F$2:$F$5743,"REFUND") -> 0 | O85: =IF(AND(G85="Paid",K85=0),"Paid, no payment",IF(AND(OR(G85="Failed",G85="Cancelled"),K85>0),"Payment on failed/cancelled",IF(K85>1,"Duplicate charge",IF(AND(K85=1,ROUND(L85-I85,2)<>0),"Amount difference",IF(AND(G85="Refunded",M85=0),"Refunded, no refund",IF(AND(G85<>"Refunded",M85>0),"Refund, order not Refunded",IF(AND(M85>0,ROUND(N85-I85,2)<>0),"Refund amount differs","OK"))))))) -> OK | P85: =IF(O85="OK",0,IF(O85="Paid, no payment",I85,IF(O85="Payment on failed/cancelled",L85,IF(OR(O85="Duplicate charge",O85="Amount difference"),L85-I85,IF(O85="Refunded, no refund",I85,N85))))) -> 0
A86: ORD26000085 | B86: 2026-09-29 | C86: CUST59857 | D86: Ahmedabad | E86: Card | F86: 3798.0 | G86: Paid | H86: =IF(MID(B86,5,1)="-",DATE(LEFT(B86,4),MID(B86,6,2),RIGHT(B86,2)),DATE(RIGHT(B86,4),MID(B86,4,2),LEFT(B86,2))) -> 46294 | I86: =VALUE(SUBSTITUTE(F86,",","")) -> 3798 | J86: =IF(TRIM(D86)="","Unknown",TRIM(D86)) -> Ahmedabad | K86: =COUNTIFS(pg_transaction_cleaned!$O$2:$O$5743,A86,pg_transaction_cleaned!$F$2:$F$5743,"CAPTURE") -> 1 | L86: =SUMIFS(pg_transaction_cleaned!$H$2:$H$5743,pg_transaction_cleaned!$O$2:$O$5743,A86,pg_transaction_cleaned!$F$2:$F$5743,"CAPTURE") -> 3798 | M86: =COUNTIFS(pg_transaction_cleaned!$O$2:$O$5743,A86,pg_transaction_cleaned!$F$2:$F$5743,"REFUND") -> 0 | N86: =SUMIFS(pg_transaction_cleaned!$H$2:$H$5743,pg_transaction_cleaned!$O$2:$O$5743,A86,pg_transaction_cleaned!$F$2:$F$5743,"REFUND") -> 0 | O86: =IF(AND(G86="Paid",K86=0),"Paid, no payment",IF(AND(OR(G86="Failed",G86="Cancelled"),K86>0),"Payment on failed/cancelled",IF(K86>1,"Duplicate charge",IF(AND(K86=1,ROUND(L86-I86,2)<>0),"Amount difference",IF(AND(G86="Refunded",M86=0),"Refunded, no refund",IF(AND(G86<>"Refunded",M86>0),"Refund, order not Refunded",IF(AND(M86>0,ROUND(N86-I86,2)<>0),"Refund amount differs","OK"))))))) -> OK | P86: =IF(O86="OK",0,IF(O86="Paid, no payment",I86,IF(O86="Payment on failed/cancelled",L86,IF(OR(O86="Duplicate charge",O86="Amount difference"),L86-I86,IF(O86="Refunded, no refund",I86,N86))))) -> 0
A87: ORD26000086 | B87: 2026-09-01 | C87: CUST64921 | D87: Jaipur | E87: NetBanking | F87: 799.0 | G87: Paid | H87: =IF(MID(B87,5,1)="-",DATE(LEFT(B87,4),MID(B87,6,2),RIGHT(B87,2)),DATE(RIGHT(B87,4),MID(B87,4,2),LEFT(B87,2))) -> 46266 | I87: =VALUE(SUBSTITUTE(F87,",","")) -> 799 | J87: =IF(TRIM(D87)="","Unknown",TRIM(D87)) -> Jaipur | K87: =COUNTIFS(pg_transaction_cleaned!$O$2:$O$5743,A87,pg_transaction_cleaned!$F$2:$F$5743,"CAPTURE") -> 1 | L87: =SUMIFS(pg_transaction_cleaned!$H$2:$H$5743,pg_transaction_cleaned!$O$2:$O$5743,A87,pg_transaction_cleaned!$F$2:$F$5743,"CAPTURE") -> 799 | M87: =COUNTIFS(pg_transaction_cleaned!$O$2:$O$5743,A87,pg_transaction_cleaned!$F$2:$F$5743,"REFUND") -> 0 | N87: =SUMIFS(pg_transaction_cleaned!$H$2:$H$5743,pg_transaction_cleaned!$O$2:$O$5743,A87,pg_transaction_cleaned!$F$2:$F$5743,"REFUND") -> 0 | O87: =IF(AND(G87="Paid",K87=0),"Paid, no payment",IF(AND(OR(G87="Failed",G87="Cancelled"),K87>0),"Payment on failed/cancelled",IF(K87>1,"Duplicate charge",IF(AND(K87=1,ROUND(L87-I87,2)<>0),"Amount difference",IF(AND(G87="Refunded",M87=0),"Refunded, no refund",IF(AND(G87<>"Refunded",M87>0),"Refund, order not Refunded",IF(AND(M87>0,ROUND(N87-I87,2)<>0),"Refund amount differs","OK"))))))) -> OK | P87: =IF(O87="OK",0,IF(O87="Paid, no payment",I87,IF(O87="Payment on failed/cancelled",L87,IF(OR(O87="Duplicate charge",O87="Amount difference"),L87-I87,IF(O87="Refunded, no refund",I87,N87))))) -> 0
A88: ORD26000087 | B88: 24-09-2026 | C88: CUST45774 | D88: Kolkata | E88: UPI | F88: 9297.0 | G88: Failed | H88: =IF(MID(B88,5,1)="-",DATE(LEFT(B88,4),MID(B88,6,2),RIGHT(B88,2)),DATE(RIGHT(B88,4),MID(B88,4,2),LEFT(B88,2))) -> 46289 | I88: =VALUE(SUBSTITUTE(F88,",","")) -> 9297 | J88: =IF(TRIM(D88)="","Unknown",TRIM(D88)) -> Kolkata | K88: =COUNTIFS(pg_transaction_cleaned!$O$2:$O$5743,A88,pg_transaction_cleaned!$F$2:$F$5743,"CAPTURE") -> 0 | L88: =SUMIFS(pg_transaction_cleaned!$H$2:$H$5743,pg_transaction_cleaned!$O$2:$O$5743,A88,pg_transaction_cleaned!$F$2:$F$5743,"CAPTURE") -> 0 | M88: =COUNTIFS(pg_transaction_cleaned!$O$2:$O$5743,A88,pg_transaction_cleaned!$F$2:$F$5743,"REFUND") -> 0 | N88: =SUMIFS(pg_transaction_cleaned!$H$2:$H$5743,pg_transaction_cleaned!$O$2:$O$5743,A88,pg_transaction_cleaned!$F$2:$F$5743,"REFUND") -> 0 | O88: =IF(AND(G88="Paid",K88=0),"Paid, no payment",IF(AND(OR(G88="Failed",G88="Cancelled"),K88>0),"Payment on failed/cancelled",IF(K88>1,"Duplicate charge",IF(AND(K88=1,ROUND(L88-I88,2)<>0),"Amount difference",IF(AND(G88="Refunded",M88=0),"Refunded, no refund",IF(AND(G88<>"Refunded",M88>0),"Refund, order not Refunded",IF(AND(M88>0,ROUND(N88-I88,2)<>0),"Refund amount differs","OK"))))))) -> OK | P88: =IF(O88="OK",0,IF(O88="Paid, no payment",I88,IF(O88="Payment on failed/cancelled",L88,IF(OR(O88="Duplicate charge",O88="Amount difference"),L88-I88,IF(O88="Refunded, no refund",I88,N88))))) -> 0
A89: ORD26000088 | B89: 2026-09-16 | C89: CUST62994 | D89: Delhi | E89: Card | F89: 1299.0 | G89: Paid | H89: =IF(MID(B89,5,1)="-",DATE(LEFT(B89,4),MID(B89,6,2),RIGHT(B89,2)),DATE(RIGHT(B89,4),MID(B89,4,2),LEFT(B89,2))) -> 46281 | I89: =VALUE(SUBSTITUTE(F89,",","")) -> 1299 | J89: =IF(TRIM(D89)="","Unknown",TRIM(D89)) -> Delhi | K89: =COUNTIFS(pg_transaction_cleaned!$O$2:$O$5743,A89,pg_transaction_cleaned!$F$2:$F$5743,"CAPTURE") -> 1 | L89: =SUMIFS(pg_transaction_cleaned!$H$2:$H$5743,pg_transaction_cleaned!$O$2:$O$5743,A89,pg_transaction_cleaned!$F$2:$F$5743,"CAPTURE") -> 1299 | M89: =COUNTIFS(pg_transaction_cleaned!$O$2:$O$5743,A89,pg_transaction_cleaned!$F$2:$F$5743,"REFUND") -> 0 | N89: =SUMIFS(pg_transaction_cleaned!$H$2:$H$5743,pg_transaction_cleaned!$O$2:$O$5743,A89,pg_transaction_cleaned!$F$2:$F$5743,"REFUND") -> 0 | O89: =IF(AND(G89="Paid",K89=0),"Paid, no payment",IF(AND(OR(G89="Failed",G89="Cancelled"),K89>0),"Payment on failed/cancelled",IF(K89>1,"Duplicate charge",IF(AND(K89=1,ROUND(L89-I89,2)<>0),"Amount difference",IF(AND(G89="Refunded",M89=0),"Refunded, no refund",IF(AND(G89<>"Refunded",M89>0),"Refund, order not Refunded",IF(AND(M89>0,ROUND(N89-I89,2)<>0),"Refund amount differs","OK"))))))) -> OK | P89: =IF(O89="OK",0,IF(O89="Paid, no payment",I89,IF(O89="Payment on failed/cancelled",L89,IF(OR(O89="Duplicate charge",O89="Amount difference"),L89-I89,IF(O89="Refunded, no refund",I89,N89))))) -> 0
A90: ORD26000089 | B90: 27-09-2026 | C90: CUST87580 | D90: Lucknow | E90: Wallet | F90: 2998.0 | G90: Paid | H90: =IF(MID(B90,5,1)="-",DATE(LEFT(B90,4),MID(B90,6,2),RIGHT(B90,2)),DATE(RIGHT(B90,4),MID(B90,4,2),LEFT(B90,2))) -> 46292 | I90: =VALUE(SUBSTITUTE(F90,",","")) -> 2998 | J90: =IF(TRIM(D90)="","Unknown",TRIM(D90)) -> Lucknow | K90: =COUNTIFS(pg_transaction_cleaned!$O$2:$O$5743,A90,pg_transaction_cleaned!$F$2:$F$5743,"CAPTURE") -> 1 | L90: =SUMIFS(pg_transaction_cleaned!$H$2:$H$5743,pg_transaction_cleaned!$O$2:$O$5743,A90,pg_transaction_cleaned!$F$2:$F$5743,"CAPTURE") -> 2998 | M90: =COUNTIFS(pg_transaction_cleaned!$O$2:$O$5743,A90,pg_transaction_cleaned!$F$2:$F$5743,"REFUND") -> 0 | N90: =SUMIFS(pg_transaction_cleaned!$H$2:$H$5743,pg_transaction_cleaned!$O$2:$O$5743,A90,pg_transaction_cleaned!$F$2:$F$5743,"REFUND") -> 0 | O90: =IF(AND(G90="Paid",K90=0),"Paid, no payment",IF(AND(OR(G90="Failed",G90="Cancelled"),K90>0),"Payment on failed/cancelled",IF(K90>1,"Duplicate charge",IF(AND(K90=1,ROUND(L90-I90,2)<>0),"Amount difference",IF(AND(G90="Refunded",M90=0),"Refunded, no refund",IF(AND(G90<>"Refunded",M90>0),"Refund, order not Refunded",IF(AND(M90>0,ROUND(N90-I90,2)<>0),"Refund amount differs","OK"))))))) -> OK | P90: =IF(O90="OK",0,IF(O90="Paid, no payment",I90,IF(O90="Payment on failed/cancelled",L90,IF(OR(O90="Duplicate charge",O90="Amount difference"),L90-I90,IF(O90="Refunded, no refund",I90,N90))))) -> 0
A91: ORD26000090 | B91: 22-09-2026 | C91: CUST70515 | D91: Delhi | E91: UPI | F91: 349.0 | G91: Paid | H91: =IF(MID(B91,5,1)="-",DATE(LEFT(B91,4),MID(B91,6,2),RIGHT(B91,2)),DATE(RIGHT(B91,4),MID(B91,4,2),LEFT(B91,2))) -> 46287 | I91: =VALUE(SUBSTITUTE(F91,",","")) -> 349 | J91: =IF(TRIM(D91)="","Unknown",TRIM(D91)) -> Delhi | K91: =COUNTIFS(pg_transaction_cleaned!$O$2:$O$5743,A91,pg_transaction_cleaned!$F$2:$F$5743,"CAPTURE") -> 1 | L91: =SUMIFS(pg_transaction_cleaned!$H$2:$H$5743,pg_transaction_cleaned!$O$2:$O$5743,A91,pg_transaction_cleaned!$F$2:$F$5743,"CAPTURE") -> 349 | M91: =COUNTIFS(pg_transaction_cleaned!$O$2:$O$5743,A91,pg_transaction_cleaned!$F$2:$F$5743,"REFUND") -> 0 | N91: =SUMIFS(pg_transaction_cleaned!$H$2:$H$5743,pg_transaction_cleaned!$O$2:$O$5743,A91,pg_transaction_cleaned!$F$2:$F$5743,"REFUND") -> 0 | O91: =IF(AND(G91="Paid",K91=0),"Paid, no payment",IF(AND(OR(G91="Failed",G91="Cancelled"),K91>0),"Payment on failed/cancelled",IF(K91>1,"Duplicate charge",IF(AND(K91=1,ROUND(L91-I91,2)<>0),"Amount difference",IF(AND(G91="Refunded",M91=0),"Refunded, no refund",IF(AND(G91<>"Refunded",M91>0),"Refund, order not Refunded",IF(AND(M91>0,ROUND(N91-I91,2)<>0),"Refund amount differs","OK"))))))) -> OK | P91: =IF(O91="OK",0,IF(O91="Paid, no payment",I91,IF(O91="Payment on failed/cancelled",L91,IF(OR(O91="Duplicate charge",O91="Amount difference"),L91-I91,IF(O91="Refunded, no refund",I91,N91))))) -> 0
A92: ORD26000091 | B92: 02-09-2026 | C92: CUST54236 | D92: Kolkata | E92: UPI | F92: 1299.0 | G92: Paid | H92: =IF(MID(B92,5,1)="-",DATE(LEFT(B92,4),MID(B92,6,2),RIGHT(B92,2)),DATE(RIGHT(B92,4),MID(B92,4,2),LEFT(B92,2))) -> 46267 | I92: =VALUE(SUBSTITUTE(F92,",","")) -> 1299 | J92: =IF(TRIM(D92)="","Unknown",TRIM(D92)) -> Kolkata | K92: =COUNTIFS(pg_transaction_cleaned!$O$2:$O$5743,A92,pg_transaction_cleaned!$F$2:$F$5743,"CAPTURE") -> 1 | L92: =SUMIFS(pg_transaction_cleaned!$H$2:$H$5743,pg_transaction_cleaned!$O$2:$O$5743,A92,pg_transaction_cleaned!$F$2:$F$5743,"CAPTURE") -> 1299 | M92: =COUNTIFS(pg_transaction_cleaned!$O$2:$O$5743,A92,pg_transaction_cleaned!$F$2:$F$5743,"REFUND") -> 0 | N92: =SUMIFS(pg_transaction_cleaned!$H$2:$H$5743,pg_transaction_cleaned!$O$2:$O$5743,A92,pg_transaction_cleaned!$F$2:$F$5743,"REFUND") -> 0 | O92: =IF(AND(G92="Paid",K92=0),"Paid, no payment",IF(AND(OR(G92="Failed",G92="Cancelled"),K92>0),"Payment on failed/cancelled",IF(K92>1,"Duplicate charge",IF(AND(K92=1,ROUND(L92-I92,2)<>0),"Amount difference",IF(AND(G92="Refunded",M92=0),"Refunded, no refund",IF(AND(G92<>"Refunded",M92>0),"Refund, order not Refunded",IF(AND(M92>0,ROUND(N92-I92,2)<>0),"Refund amount differs","OK"))))))) -> OK | P92: =IF(O92="OK",0,IF(O92="Paid, no payment",I92,IF(O92="Payment on failed/cancelled",L92,IF(OR(O92="Duplicate charge",O92="Amount difference"),L92-I92,IF(O92="Refunded, no refund",I92,N92))))) -> 0
A93: ORD26000092 | B93: 09-09-2026 | C93: CUST80702 | D93: Mumbai | E93: UPI | F93: 8798.0 | G93: Paid | H93: =IF(MID(B93,5,1)="-",DATE(LEFT(B93,4),MID(B93,6,2),RIGHT(B93,2)),DATE(RIGHT(B93,4),MID(B93,4,2),LEFT(B93,2))) -> 46274 | I93: =VALUE(SUBSTITUTE(F93,",","")) -> 8798 | J93: =IF(TRIM(D93)="","Unknown",TRIM(D93)) -> Mumbai | K93: =COUNTIFS(pg_transaction_cleaned!$O$2:$O$5743,A93,pg_transaction_cleaned!$F$2:$F$5743,"CAPTURE") -> 1 | L93: =SUMIFS(pg_transaction_cleaned!$H$2:$H$5743,pg_transaction_cleaned!$O$2:$O$5743,A93,pg_transaction_cleaned!$F$2:$F$5743,"CAPTURE") -> 8798 | M93: =COUNTIFS(pg_transaction_cleaned!$O$2:$O$5743,A93,pg_transaction_cleaned!$F$2:$F$5743,"REFUND") -> 0 | N93: =SUMIFS(pg_transaction_cleaned!$H$2:$H$5743,pg_transaction_cleaned!$O$2:$O$5743,A93,pg_transaction_cleaned!$F$2:$F$5743,"REFUND") -> 0 | O93: =IF(AND(G93="Paid",K93=0),"Paid, no payment",IF(AND(OR(G93="Failed",G93="Cancelled"),K93>0),"Payment on failed/cancelled",IF(K93>1,"Duplicate charge",IF(AND(K93=1,ROUND(L93-I93,2)<>0),"Amount difference",IF(AND(G93="Refunded",M93=0),"Refunded, no refund",IF(AND(G93<>"Refunded",M93>0),"Refund, order not Refunded",IF(AND(M93>0,ROUND(N93-I93,2)<>0),"Refund amount differs","OK"))))))) -> OK | P93: =IF(O93="OK",0,IF(O93="Paid, no payment",I93,IF(O93="Payment on failed/cancelled",L93,IF(OR(O93="Duplicate charge",O93="Amount difference"),L93-I93,IF(O93="Refunded, no refund",I93,N93))))) -> 0
... A126: ORD26000125 | B126: 04-09-2026 | C126: CUST28643 | D126: Pune | E126: UPI | F126: 3598.0 | G126: Paid | H126: =IF(MID(B126,5,1)="-",DATE(LEFT(B126,4),MID(B126,6,2),RIGHT(B126,2)),DATE(RIGHT(B126,4),MID(B126,4,2),LEFT(B126,2))) -> 46269 | I126: =VALUE(SUBSTITUTE(F126,",","")) -> 3598 | J126: =IF(TRIM(D126)="","Unknown",TRIM(D126)) -> Pune | K126: =COUNTIFS(pg_transaction_cleaned!$O$2:$O$5743,A126,pg_transaction_cleaned!$F$2:$F$5743,"CAPTURE") -> 1 | L126: =SUMIFS(pg_transaction_cleaned!$H$2:$H$5743,pg_transaction_cleaned!$O$2:$O$5743,A126,pg_transaction_cleaned!$F$2:$F$5743,"CAPTURE") -> 3598 | M126: =COUNTIFS(pg_transaction_cleaned!$O$2:$O$5743,A126,pg_transaction_cleaned!$F$2:$F$5743,"REFUND") -> 0 | N126: =SUMIFS(pg_transaction_cleaned!$H$2:$H$5743,pg_transaction_cleaned!$O$2:$O$5743,A126,pg_transaction_cleaned!$F$2:$F$5743,"REFUND") -> 0 | O126: =IF(AND(G126="Paid",K126=0),"Paid, no payment",IF(AND(OR(G126="Failed",G126="Cancelled"),K126>0),"Payment on failed/cancelled",IF(K126>1,"Duplicate charge",IF(AND(K126=1,ROUND(L126-I126,2)<>0),"Amount difference",IF(AND(G126="Refunded",M126=0),"Refunded, no refund",IF(AND(G126<>"Refunded",M126>0),"Refund, order not Refunded",IF(AND(M126>0,ROUND(N126-I126,2)<>0),"Refund amount differs","OK"))))))) -> OK | P126: =IF(O126="OK",0,IF(O126="Paid, no payment",I126,IF(O126="Payment on failed/cancelled",L126,IF(OR(O126="Duplicate charge",O126="Amount difference"),L126-I126,IF(O126="Refunded, no refund",I126,N126))))) -> 0
A127: ORD26000126 | B127: 02-09-2026 | C127: CUST84607 | E127: Card | F127: 4999.0 | G127: Paid | H127: =IF(MID(B127,5,1)="-",DATE(LEFT(B127,4),MID(B127,6,2),RIGHT(B127,2)),DATE(RIGHT(B127,4),MID(B127,4,2),LEFT(B127,2))) -> 46267 | I127: =VALUE(SUBSTITUTE(F127,",","")) -> 4999 | J127: =IF(TRIM(D127)="","Unknown",TRIM(D127)) -> Unknown | K127: =COUNTIFS(pg_transaction_cleaned!$O$2:$O$5743,A127,pg_transaction_cleaned!$F$2:$F$5743,"CAPTURE") -> 1 | L127: =SUMIFS(pg_transaction_cleaned!$H$2:$H$5743,pg_transaction_cleaned!$O$2:$O$5743,A127,pg_transaction_cleaned!$F$2:$F$5743,"CAPTURE") -> 4999 | M127: =COUNTIFS(pg_transaction_cleaned!$O$2:$O$5743,A127,pg_transaction_cleaned!$F$2:$F$5743,"REFUND") -> 0 | N127: =SUMIFS(pg_transaction_cleaned!$H$2:$H$5743,pg_transaction_cleaned!$O$2:$O$5743,A127,pg_transaction_cleaned!$F$2:$F$5743,"REFUND") -> 0 | O127: =IF(AND(G127="Paid",K127=0),"Paid, no payment",IF(AND(OR(G127="Failed",G127="Cancelled"),K127>0),"Payment on failed/cancelled",IF(K127>1,"Duplicate charge",IF(AND(K127=1,ROUND(L127-I127,2)<>0),"Amount difference",IF(AND(G127="Refunded",M127=0),"Refunded, no refund",IF(AND(G127<>"Refunded",M127>0),"Refund, order not Refunded",IF(AND(M127>0,ROUND(N127-I127,2)<>0),"Refund amount differs","OK"))))))) -> OK | P127: =IF(O127="OK",0,IF(O127="Paid, no payment",I127,IF(O127="Payment on failed/cancelled",L127,IF(OR(O127="Duplicate charge",O127="Amount difference"),L127-I127,IF(O127="Refunded, no refund",I127,N127))))) -> 0
